Workbook

Sheet Loss development triangles
B6: Combined Cumulative Net Losses Across All Business
B8: Years in which losses where incurred | C8: 0 | D8: 1 | E8: 2 | F8: 3 | G8: 4 | H8: 5 | I8: 6 | J8: 7 | K8: 8 | L8: 9
B9: 2016 | C9: 11280638 | D9: 14471185 | E9: 15708265 | F9: 16621517 | G9: 17081334 | H9: 17315214 | I9: 17520116 | J9: 17638848 | K9: 17686048 | L9: 17714740
B10: 2017 | C10: 11170884 | D10: 14574885 | E10: 15992709 | F10: 16641062 | G10: 17120078 | H10: 17464159 | I10: 17646262 | J10: 17742349 | K10: 17796939 | L10: 0
B11: 2018 | C11: 11547535 | D11: 15165858 | E11: 16311589 | F11: 17045222 | G11: 17740647 | H11: 18111387 | I11: 18370396 | J11: 18446344 | K11: 0 | L11: 0
B12: 2019 | C12: 12121015 | D12: 16056837 | E12: 17504926 | F12: 18673151 | G12: 19400551 | H12: 19737302 | I12: 19879787 | J12: 0 | K12: 0 | L12: 0
B13: 2020 | C13: 11312244 | D13: 14821595 | E13: 16463026 | F13: 17427249 | G13: 17949629 | H13: 18173277 | I13: 0 | J13: 0 | K13: 0 | L13: 0
B14: 2021 | C14: 14232658 | D14: 20321637 | E14: 22273352 | F14: 23451116 | G14: 24022657 | H14: 0 | I14: 0 | J14: 0 | K14: 0 | L14: 0
B15: 2022 | C15: 15986304 | D15: 23228953 | E15: 25609947 | F15: 26753730 | G15: 0 | H15: 0 | I15: 0 | J15: 0 | K15: 0 | L15: 0
B16: 2023 | C16: 18564718 | D16: 26008822 | E16: 28385184 | F16: 0 | G16: 0 | H16: 0 | I16: 0 | J16: 0 | K16: 0 | L16: 0
B17: 2024 | C17: 18456817 | D17: 25767725 | E17: 0 | F17: 0 | G17: 0 | H17: 0 | I17: 0 | J17: 0 | K17: 0 | L17: 0
B18: 2025 | C18: 18654478 | D18: 0 | E18: 0 | F18: 0 | G18: 0 | H18: 0 | I18: 0 | J18: 0 | K18: 0 | L18: 0
B26: Cumulative Net losses For Homeowners and Farmowners
B28: Years in which losses where incurred | C28: 0 | D28: 1 | E28: 2 | F28: 3 | G28: 4 | H28: 5 | I28: 6 | J28: 7 | K28: 8 | L28: 9
B29: 2016 | C29: 2951212 | D29: 3670988 | E29: 3794087 | F29: 3854258 | G29: 3883309 | H29: 3896012 | I29: 3908156 | J29: 3913496 | K29: 3916830 | L29: 3921589
B30: 2017 | C30: 3226384 | D30: 4211001 | E30: 4388324 | F30: 4273926 | G30: 4292278 | H30: 4273151 | I30: 4279105 | J30: 4283872 | K30: 4289311 | L30: 0
B31: 2018 | C31: 3426752 | D31: 4441598 | E31: 4328525 | F31: 4303357 | G31: 4375282 | H31: 4401207 | I31: 4417276 | J31: 4428696 | K31: 0 | L31: 0
B32: 2019 | C32: 3320519 | D32: 4280049 | E32: 4431447 | F32: 4511769 | G32: 4558654 | H32: 4582488 | I32: 4590735 | J32: 0 | K32: 0 | L32: 0
B33: 2020 | C33: 3926387 | D33: 5033659 | E33: 5244109 | F33: 5326099 | G33: 5369591 | H33: 5400944 | I33: 0 | J33: 0 | K33: 0 | L33: 0
B34: 2021 | C34: 4114365 | D34: 5629081 | E34: 5841364 | F34: 5972356 | G34: 6023524 | H34: 0 | I34: 0 | J34: 0 | K34: 0 | L34: 0
B35: 2022 | C35: 3697440 | D35: 5580955 | E35: 5826612 | F35: 5934200 | G35: 0 | H35: 0 | I35: 0 | J35: 0 | K35: 0 | L35: 0
B36: 2023 | C36: 5418523 | D36: 7317741 | E36: 7680906 | F36: 0 | G36: 0 | H36: 0 | I36: 0 | J36: 0 | K36: 0 | L36: 0
B37: 2024 | C37: 5366128 | D37: 7451121 | E37: 0 | F37: 0 | G37: 0 | H37: 0 | I37: 0 | J37: 0 | K37: 0 | L37: 0
B38: 2025 | C38: 5725112 | D38: 0 | E38: 0 | F38: 0 | G38: 0 | H38: 0 | I38: 0 | J38: 0 | K38: 0 | L38: 0
B44: Cumulative Net losses For PRIVATE PASSENGER AUTO LIABILITY/MEDICAL
B46: Years in which losses where incurred | C46: 0 | D46: 1 | E46: 2 | F46: 3 | G46: 4 | H46: 5 | I46: 6 | J46: 7 | K46: 8 | L46: 9
B47: 2016 | C47: 3264857 | D47: 5433994 | E47: 6461154 | F47: 7223215 | G47: 7605404 | H47: 7801006 | I47: 7959361 | J47: 8054272 | K47: 8089009 | L47: 8105529
B48: 2017 | C48: 2946641 | D48: 5035056 | E48: 6187092 | F48: 6898103 | G48: 7322015 | H48: 7620624 | I48: 7765462 | J48: 7844848 | K48: 7883522 | L48: 0
B49: 2018 | C49: 3011834 | D49: 5292216 | E49: 6493718 | F49: 7197833 | G49: 7725378 | H49: 7995706 | I49: 8204517 | J49: 8252686 | K49: 0 | L49: 0
B50: 2019 | C50: 3252576 | D50: 5858754 | E50: 7074694 | F50: 7993295 | G50: 8535303 | H50: 8767735 | I50: 8869267 | J50: 0 | K50: 0 | L50: 0
B51: 2020 | C51: 2530357 | D51: 4561663 | E51: 5817607 | F51: 6546020 | G51: 6913311 | H51: 7056466 | I51: 0 | J51: 0 | K51: 0 | L51: 0
B52: 2021 | C52: 3144511 | D52: 6726531 | E52: 8287997 | F52: 9149454 | G52: 9521686 | H52: 0 | I52: 0 | J52: 0 | K52: 0 | L52: 0
B53: 2022 | C53: 3903265 | D53: 8028546 | E53: 9912100 | F53: 10740399 | G53: 0 | H53: 0 | I53: 0 | J53: 0 | K53: 0 | L53: 0
B54: 2023 | C54: 4417124 | D54: 8881824 | E54: 10699665 | F54: 0 | G54: 0 | H54: 0 | I54: 0 | J54: 0 | K54: 0 | L54: 0
B55: 2024 | C55: 4719549 | D55: 9031737 | E55: 0 | F55: 0 | G55: 0 | H55: 0 | I55: 0 | J55: 0 | K55: 0 | L55: 0
B56: 2025 | C56: 5098536 | D56: 0 | E56: 0 | F56: 0 | G56: 0 | H56: 0 | I56: 0 | J56: 0 | K56: 0 | L56: 0
B62: Cumulative Net losses For COMMERCIAL AUTO/TRUCK LIABILITY/MEDICAL
B64: Years in which losses where incurred | C64: 0 | D64: 1 | E64: 2 | F64: 3 | G64: 4 | H64: 5 | I64: 6 | J64: 7 | K64: 8 | L64: 9
B65: 2016 | C65: 43817 | D65: 90782 | E65: 132929 | F65: 173070 | G65: 197804 | H65: 204865 | I65: 219835 | J65: 229766 | K65: 232854 | L65: 237230
B66: 2017 | C66: 34518 | D66: 73053 | E66: 110453 | F66: 138828 | G66: 138536 | H66: 165484 | I66: 184344 | J66: 189838 | K66: 194841 | L66: 0
...

Sheet year to ultimate LDF
C8: Volume weighted loss development factor | E8: Year to ultimate loss development factor
C9: f1 | D9: =SUM('Loss development triangles'!D9:D17)/SUM('Loss development triangles'!C9:C17) -> 1.3669179 | E9: 1 to ultimate | F9: =PRODUCT(D9:D17) -> 1.6845809
C10: f2 | D10: =SUM('Loss development triangles'!E9:E16)/SUM('Loss development triangles'!D9:D16) -> 1.0940148 | E10: 2 to ultimate | F10: =PRODUCT(D10:D17) -> 1.2323936
C11: f3 | D11: =SUM('Loss development triangles'!F9:F15)/SUM('Loss development triangles'!E9:E15) -> 1.0519716 | E11: 3 to ultimate | F11: =PRODUCT(D11:D17) -> 1.1264871
C12: f4 | D12: =SUM('Loss development triangles'!G9:G14)/SUM('Loss development triangles'!F9:F14) -> 1.0314546 | E12: 4 to ultimate | F12: =PRODUCT(D12:D17) -> 1.0708341
C13: f5 | D13: =SUM('Loss development triangles'!H9:H13)/SUM('Loss development triangles'!G9:G13) -> 1.0169007 | E13: 5 to ultimate | F13: =PRODUCT(D13:D17) -> 1.0381787
C14: f6 | D14: =SUM('Loss development triangles'!I9:I12)/SUM('Loss development triangles'!H9:H12) -> 1.0108567 | E14: 6 to ultimate | F14: =PRODUCT(D14:D17) -> 1.0209243
C15: f7 | D15: =SUM('Loss development triangles'!J9:J11)/SUM('Loss development triangles'!I9:I11) -> 1.0054312 | E15: 7 to ultimate | F15: =PRODUCT(D15:D17) -> 1.0099595
C16: f8 | D16: =SUM('Loss development triangles'!K9:K10)/SUM('Loss development triangles'!J9:J10) -> 1.002877 | E16: 8 to ultimate | F16: =PRODUCT(D16:D17) -> 1.0045039
C17: f9 | D17: =SUM('Loss development triangles'!L9)/SUM('Loss development triangles'!K9) -> 1.0016223 | E17: 9 to ultimate | F17: =PRODUCT(D17) -> 1.0016223
C18: f10 | D18: 1 | E18: 10 to ultimate | F18: 1
C28: Volume weighted loss development factor | E28: Year to ultimate loss development factor
C29: f1 | D29: =SUM('Loss development triangles'!D29:D37)/SUM('Loss development triangles'!C29:C37) -> 1.3432798 | E29: 1 to ultimate | F29: =PRODUCT(D29:D37) -> 1.4291578
C30: f2 | D30: =SUM('Loss development triangles'!E29:E36)/SUM('Loss development triangles'!D29:D36) -> 1.0341168 | E30: 2 to ultimate | F30: =PRODUCT(D30:D37) -> 1.0639316
C31: f3 | D31: =SUM('Loss development triangles'!F29:F35)/SUM('Loss development triangles'!E29:E35) -> 1.0094964 | E31: 3 to ultimate | F31: =PRODUCT(D31:D37) -> 1.0288312
C32: f4 | D32: =SUM('Loss development triangles'!G29:G34)/SUM('Loss development triangles'!F29:F34) -> 1.0092371 | E32: 4 to ultimate | F32: =PRODUCT(D32:D37) -> 1.0191529
C33: f5 | D33: =SUM('Loss development triangles'!H29:H33)/SUM('Loss development triangles'!G29:G33) -> 1.0033226 | E33: 5 to ultimate | F33: =PRODUCT(D33:D37) -> 1.009825
C34: f6 | D34: =SUM('Loss development triangles'!I29:I32)/SUM('Loss development triangles'!H29:H32) -> 1.0024727 | E34: 6 to ultimate | F34: =PRODUCT(D34:D37) -> 1.0064809
C35: f7 | D35: =SUM('Loss development triangles'!J29:J31)/SUM('Loss development triangles'!I29:I31) -> 1.0017079 | E35: 7 to ultimate | F35: =PRODUCT(D35:D37) -> 1.0039983
C36: f8 | D36: =SUM('Loss development triangles'!K29:K30)/SUM('Loss development triangles'!J29:J30) -> 1.0010702 | E36: 8 to ultimate | F36: =PRODUCT(D36:D37) -> 1.0022865
C37: f9 | D37: =SUM('Loss development triangles'!L29)/SUM('Loss development triangles'!K29) -> 1.001215 | E37: 9 to ultimate | F37: =PRODUCT(D37) -> 1.001215
C38: f10 | D38: 1 | E38: 10 to ultimate | F38: 1
C46: Volume weighted loss development factor | E46: Year to ultimate loss development factor
C47: f1 | D47: =SUM('Loss development triangles'!D47:D55)/SUM('Loss development triangles'!C47:C55) -> 1.8867898 | E47: 1 to ultimate | F47: =PRODUCT(D47:D55) -> 2.8897686
C48: f2 | D48: =SUM('Loss development triangles'!E47:E54)/SUM('Loss development triangles'!D47:D54) -> 1.2231184 | E48: 2 to ultimate | F48: =PRODUCT(D48:D55) -> 1.5315795
C49: f3 | D49: =SUM('Loss development triangles'!F47:F53)/SUM('Loss development triangles'!E47:E53) -> 1.1097646 | E49: 3 to ultimate | F49: =PRODUCT(D49:D55) -> 1.2521923
C50: f4 | D50: =SUM('Loss development triangles'!G47:G52)/SUM('Loss development triangles'!F47:F52) -> 1.0581048 | E50: 4 to ultimate | F50: =PRODUCT(D50:D55) -> 1.1283405
C51: f5 | D51: =SUM('Loss development triangles'!H47:H51)/SUM('Loss development triangles'!G47:G51) -> 1.0299235 | E51: 5 to ultimate | F51: =PRODUCT(D51:D55) -> 1.0663787
C52: f6 | D52: =SUM('Loss development triangles'!I47:I50)/SUM('Loss development triangles'!H47:H50) -> 1.0190628 | E52: 6 to ultimate | F52: =PRODUCT(D52:D55) -> 1.0353961
C53: f7 | D53: =SUM('Loss development triangles'!J47:J49)/SUM('Loss development triangles'!I47:I49) -> 1.0092968 | E53: 7 to ultimate | F53: =PRODUCT(D53:D55) -> 1.0160278
C54: f8 | D54: =SUM('Loss development triangles'!K47:K48)/SUM('Loss development triangles'!J47:J48) -> 1.0046173 | E54: 8 to ultimate | F54: =PRODUCT(D54:D55) -> 1.006669
C55: f9 | D55: =SUM('Loss development triangles'!L47)/SUM('Loss development triangles'!K47) -> 1.0020423 | E55: 9 to ultimate | F55: =PRODUCT(D55) -> 1.0020423
C56: f10 | D56: 1 | E56: 10 to ultimate | F56: 1
C64: Volume weighted loss development factor | E64: Year to ultimate loss development factor
C65: f1 | D65: =SUM('Loss development triangles'!D65:D73)/SUM('Loss development triangles'!C65:C73) -> 2.4509019 | E65: 1 to ultimate | F65: =PRODUCT(D65:D73) -> 8.3999763
C66: f2 | D66: =SUM('Loss development triangles'!E65:E72)/SUM('Loss development triangles'!D65:D72) -> 1.6408231 | E66: 2 to ultimate | F66: =PRODUCT(D66:D73) -> 3.4273001
C67: f3 | D67: =SUM('Loss development triangles'!F65:F71)/SUM('Loss development triangles'!E65:E71) -> 1.3704547 | E67: 3 to ultimate | F67: =PRODUCT(D67:D73) -> 2.0887688
C68: f4 | D68: =SUM('Loss development triangles'!G65:G70)/SUM('Loss development triangles'!F65:F70) -> 1.1977142 | E68: 4 to ultimate | F68: =PRODUCT(D68:D73) -> 1.5241428
C69: f5 | D69: =SUM('Loss development triangles'!H65:H69)/SUM('Loss development triangles'!G65:G69) -> 1.1156098 | E69: 5 to ultimate | F69: =PRODUCT(D69:D73) -> 1.272543
C70: f6 | D70: =SUM('Loss development triangles'!I65:I68)/SUM('Loss development triangles'!H65:H68) -> 1.062928 | E70: 6 to ultimate | F70: =PRODUCT(D70:D73) -> 1.1406703
...

Sheet loss reserve and loss ratio
C8: Accident Year | D8: Cumulative paid loss to date | E8: Age at latest evaluation | F8: Ultimate Loss development Factor | G8: Expected Loss(Chain Ladder Method) | H8: Loss Reserves(Chain Ladder Method) | I8: Earned Premiums | J8: Expected Loss Ratio
C9: 2016 | D9: 17714740 | E9: 9 | F9: 1 | G9: =PRODUCT(D9,F9) -> 17714740 | H9: =G9-D9 -> 0 | I9: 28365742 | J9: =(G9/I9)*100 -> 62.451178
C10: 2017 | D10: 17796939 | E10: 8 | F10: 1.0016223 | G10: =PRODUCT(D10,F10) -> 17825811 | H10: =G10-D10 -> 28871.898 | I10: 29036977 | J10: =(G10/I10)*100 -> 61.390037
C11: 2018 | D11: 18446344 | E11: 7 | F11: 1.0045039 | G11: =PRODUCT(D11,F11) -> 18529425 | H11: =G11-D11 -> 83080.762 | I11: 30384610 | J11: =(G11/I11)*100 -> 60.982928
C12: 2019 | D12: 19879787 | E12: 6 | F12: 1.0099595 | G12: =PRODUCT(D12,F12) -> 20077781 | H12: =G12-D12 -> 197993.54 | I12: 32154348 | J12: =(G12/I12)*100 -> 62.441884
C13: 2020 | D13: 18173277 | E13: 5 | F13: 1.0209243 | G13: =PRODUCT(D13,F13) -> 18553541 | H13: =G13-D13 -> 380263.81 | I13: 32004143 | J13: =(G13/I13)*100 -> 57.972309
C14: 2021 | D14: 24022657 | E14: 4 | F14: 1.0381787 | G14: =PRODUCT(D14,F14) -> 24939810 | H14: =G14-D14 -> 917152.85 | I14: 35836933 | J14: =(G14/I14)*100 -> 69.592478
C15: 2022 | D15: 26753730 | E15: 3 | F15: 1.0708341 | G15: =PRODUCT(D15,F15) -> 28648807 | H15: =G15-D15 -> 1895077.4 | I15: 39258018 | J15: =(G15/I15)*100 -> 72.975685
C16: 2023 | D16: 28385184 | E16: 2 | F16: 1.1264871 | G16: =PRODUCT(D16,F16) -> 31975544 | H16: =G16-D16 -> 3590360.3 | I16: 43412876 | J16: =(G16/I16)*100 -> 73.654517
C17: 2024 | D17: 25767725 | E17: 1 | F17: 1.2323936 | G17: =PRODUCT(D17,F17) -> 31755980 | H17: =G17-D17 -> 5988255.3 | I17: 48919086 | J17: =(G17/I17)*100 -> 64.915318
C18: 2025 | D18: 18654478 | E18: 0 | F18: 1.6845809 | G18: =PRODUCT(D18,F18) -> 31424977 | H18: =G18-D18 -> 12770499 | I18: 52969368 | J18: =(G18/I18)*100 -> 59.326698
F19: Total | G19: =SUM(G9:G18) -> 2.4144642e+08 | H19: =SUM(H9:H18) -> 25851555 | I19: =SUM(I9:I18) -> 372342101 | J19: =(G19/I19)*100 -> 64.845317
C28: Accident Year | D28: Cumulative paid loss to date | E28: Age at latest evaluation | F28: Ultimate Loss development Factor | G28: Expected Loss(Chain Ladder Method) | H28: Loss Reserves(Chain Ladder Method) | I28: Earned Premiums | J28: Expected Loss Ratio
C29: 2016 | D29: 3921589 | E29: 9 | F29: 1 | G29: =PRODUCT(D29,F29) -> 3921589 | H29: =G29-D29 -> 0 | I29: 7213328 | J29: =(G29/I29)*100 -> 54.365877
C30: 2017 | D30: 4289311 | E30: 8 | F30: 1.001215 | G30: =PRODUCT(D30,F30) -> 4294522.6 | H30: =G30-D30 -> 5211.5693 | I30: 7252088 | J30: =(G30/I30)*100 -> 59.217739
C31: 2018 | D31: 4428696 | E31: 7 | F31: 1.0022865 | G31: =PRODUCT(D31,F31) -> 4438822.4 | H31: =G31-D31 -> 10126.369 | I31: 7409282 | J31: =(G31/I31)*100 -> 59.908941
C32: 2019 | D32: 4590735 | E32: 6 | F32: 1.0039983 | G32: =PRODUCT(D32,F32) -> 4609090.2 | H32: =G32-D32 -> 18355.215 | I32: 7822918 | J32: =(G32/I32)*100 -> 58.917788
C33: 2020 | D33: 5400944 | E33: 5 | F33: 1.0064809 | G33: =PRODUCT(D33,F33) -> 5435947 | H33: =G33-D33 -> 35003.04 | I33: 8187778 | J33: =(G33/I33)*100 -> 66.390992
C34: 2021 | D34: 6023524 | E34: 4 | F34: 1.009825 | G34: =PRODUCT(D34,F34) -> 6082705.1 | H34: =G34-D34 -> 59181.096 | I34: 8524429 | J34: =(G34/I34)*100 -> 71.356159
C35: 2022 | D35: 5934200 | E35: 3 | F35: 1.0191529 | G35: =PRODUCT(D35,F35) -> 6047857.1 | H35: =G35-D35 -> 113657.05 | I35: 9723000 | J35: =(G35/I35)*100 -> 62.201554
C36: 2023 | D36: 7680906 | E36: 2 | F36: 1.0288312 | G36: =PRODUCT(D36,F36) -> 7902355.8 | H36: =G36-D36 -> 221449.83 | I36: 10949703 | J36: =(G36/I36)*100 -> 72.169591
C37: 2024 | D37: 7451121 | E37: 1 | F37: 1.0639316 | G37: =PRODUCT(D37,F37) -> 7927483.1 | H37: =G37-D37 -> 476362.06 | I37: 12616712 | J37: =(G37/I37)*100 -> 62.833193
C38: 2025 | D38: 5725112 | E38: 0 | F38: 1.4291578 | G38: =PRODUCT(D38,F38) -> 8182088.6 | H38: =G38-D38 -> 2456976.6 | I38: 14516952 | J38: =(G38/I38)*100 -> 56.362304
F39: Total | G39: =SUM(G29:G38) -> 58842461 | H39: =SUM(H29:H38) -> 3396322.9 | I39: =SUM(I29:I38) -> 94216190 | J39: =(G39/I39)*100 -> 62.454723
C46: Accident Year | D46: Cumulative paid loss to date | E46: Age at latest evaluation | F46: Ultimate Loss development Factor | G46: Expected Loss(Chain Ladder Method) | H46: Loss Reserves(Chain Ladder Method) | I46: Earned Premiums | J46: Expected Loss Ratio
C47: 2016 | D47: 8105529 | E47: 9 | F47: 1 | G47: =PRODUCT(D47,F47) -> 8105529 | H47: =G47-D47 -> 0 | I47: 11336988 | J47: =(G47/I47)*100 -> 71.496318
C48: 2017 | D48: 7883522 | E48: 8 | F48: 1.0020423 | G48: =PRODUCT(D48,F48) -> 7899622.3 | H48: =G48-D48 -> 16100.339 | I48: 11837624 | J48: =(G48/I48)*100 -> 66.733175
C49: 2018 | D49: 8252686 | E49: 7 | F49: 1.006669 | G49: =PRODUCT(D49,F49) -> 8307723.2 | H49: =G49-D49 -> 55037.219 | I49: 12381799 | J49: =(G49/I49)*100 -> 67.096253
C50: 2019 | D50: 8869267 | E50: 6 | F50: 1.0160278 | G50: =PRODUCT(D50,F50) -> 9011421.8 | H50: =G50-D50 -> 142154.79 | I50: 12827570 | J50: =(G50/I50)*100 -> 70.25042
C51: 2020 | D51: 7056466 | E51: 5 | F51: 1.0353961 | G51: =PRODUCT(D51,F51) -> 7306237.2 | H51: =G51-D51 -> 249771.24 | I51: 12336855 | J51: =(G51/I51)*100 -> 59.222851
C52: 2021 | D52: 9521686 | E52: 4 | F52: 1.0663787 | G52: =PRODUCT(D52,F52) -> 10153723 | H52: =G52-D52 -> 632037.25 | I52: 13449965 | J52: =(G52/I52)*100 -> 75.492563
C53: 2022 | D53: 10740399 | E53: 3 | F53: 1.1283405 | G53: =PRODUCT(D53,F53) -> 12118827 | H53: =G53-D53 -> 1378427.7 | I53: 14619643 | J53: =(G53/I53)*100 -> 82.894135
C54: 2023 | D54: 10699665 | E54: 2 | F54: 1.2521923 | G54: =PRODUCT(D54,F54) -> 13398039 | H54: =G54-D54 -> 2698373.6 | I54: 16660394 | J54: =(G54/I54)*100 -> 80.418498
C55: 2024 | D55: 9031737 | E55: 1 | F55: 1.5315795 | G55: =PRODUCT(D55,F55) -> 13832823 | H55: =G55-D55 -> 4801086.3 | I55: 18993672 | J55: =(G55/I55)*100 -> 72.828589
C56: 2025 | D56: 5098536 | E56: 0 | F56: 2.8897686 | G56: =PRODUCT(D56,F56) -> 14733589 | H56: =G56-D56 -> 9635053.1 | I56: 20474091 | J56: =(G56/I56)*100 -> 71.962116
F57: Total | G57: =SUM(G47:G56) -> 1.0486753e+08 | H57: =SUM(H47:H56) -> 19608042 | I57: =SUM(I47:I56) -> 144918601 | J57: =(G57/I57)*100 -> 72.36306
C64: Accident Year | D64: Cumulative paid loss to date | E64: Age at latest evaluation | F64: Ultimate Loss development Factor | G64: Expected Loss(Chain Ladder Method) | H64: Loss Reserves(Chain Ladder Method) | I64: Earned Premiums | J64: Expected Loss Ratio
C65: 2016 | D65: 237230 | E65: 9 | F65: 1 | G65: =PRODUCT(D65,F65) -> 237230 | H65: =G65-D65 -> 0 | I65: 255426 | J65: =(G65/I65)*100 -> 92.876215
C66: 2017 | D66: 194841 | E66: 8 | F66: 1.0187929 | G66: =PRODUCT(D66,F66) -> 198502.63 | H66: =G66-D66 -> 3661.6258 | I66: 260211 | J66: =(G66/I66)*100 -> 76.285255
C67: 2018 | D67: 275175 | E67: 7 | F67: 1.0384377 | G67: =PRODUCT(D67,F67) -> 285752.1 | H67: =G67-D67 -> 10577.103 | I67: 360958 | J67: =(G67/I67)*100 -> 79.164917
...

Sheet rate adequacy verdict
B8: Accident Year | C8: Earned Premiums | D8: Indicative Loss Ratio(Percentage) | E8: Target Loss Ratio%(Average ) | F8: Difference(Points) | G8: Rate Adequacy Verdict
B9: 2016 | C9: 28365742 | D9: 62.451178 | E9: 64.85 | F9: =D9-E9 -> -2.3988221 | G9: Roughly Adequate
B10: 2017 | C10: 29036977 | D10: 61.390037 | E10: 64.85 | F10: =D10-E10 -> -3.4599631 | G10: Roughly Adequate
B11: 2018 | C11: 30384610 | D11: 60.982928 | E11: 64.85 | F11: =D11-E11 -> -3.8670723 | G11: Roughly Adequate
B12: 2019 | C12: 32154348 | D12: 62.441884 | E12: 64.85 | F12: =D12-E12 -> -2.4081164 | G12: Roughly Adequate
B13: 2020 | C13: 32004143 | D13: 57.972309 | E13: 64.85 | F13: =D13-E13 -> -6.8776906 | G13: Overcharged
B14: 2021 | C14: 35836933 | D14: 69.592478 | E14: 64.85 | F14: =D14-E14 -> 4.7424784 | G14: Roughly Adequate
B15: 2022 | C15: 39258018 | D15: 72.975685 | E15: 64.85 | F15: =D15-E15 -> 8.1256845 | G15: Undercharged
B16: 2023 | C16: 43412876 | D16: 73.654517 | E16: 64.85 | F16: =D16-E16 -> 8.8045173 | G16: Undercharged
B17: 2024 | C17: 48919086 | D17: 64.915318 | E17: 64.85 | F17: =D17-E17 -> 0.065318141 | G17: Roughly Adequate
B18: 2025 | C18: 52969368 | D18: 59.326698 | E18: 64.85 | F18: =D18-E18 -> -5.5233015 | G18: Overcharged
B28: Accident Year | C28: Earned Premiums | D28: Indicative Loss Ratio(Percentage) | E28: Target Loss Ratio%(Average ) | F28: Difference(Points) | G28: Rate Adequacy Verdict
B29: 2016 | C29: 7213328 | D29: 54.365877 | E29: 62.45 | F29: =D29-E29 -> -8.0841234 | G29: Overcharged
B30: 2017 | C30: 7252088 | D30: 59.217739 | E30: 62.45 | F30: =D30-E30 -> -3.2322606 | G30: Roughly Adequate
B31: 2018 | C31: 7409282 | D31: 59.908941 | E31: 62.45 | F31: =D31-E31 -> -2.5410592 | G31: Roughly Adequate
B32: 2019 | C32: 7822918 | D32: 58.917788 | E32: 62.45 | F32: =D32-E32 -> -3.5322124 | G32: Roughly Adequate
B33: 2020 | C33: 8187778 | D33: 66.390992 | E33: 62.45 | F33: =D33-E33 -> 3.940992 | G33: Roughly Adequate
B34: 2021 | C34: 8524429 | D34: 71.356159 | E34: 62.45 | F34: =D34-E34 -> 8.9061588 | G34: Undercharged
B35: 2022 | C35: 9723000 | D35: 62.201554 | E35: 62.45 | F35: =D35-E35 -> -0.24844644 | G35: Roughly Adequate
B36: 2023 | C36: 10949703 | D36: 72.169591 | E36: 62.45 | F36: =D36-E36 -> 9.7195906 | G36: Undercharged
B37: 2024 | C37: 12616712 | D37: 62.833193 | E37: 62.45 | F37: =D37-E37 -> 0.38319347 | G37: Roughly Adequate
B38: 2025 | C38: 14516952 | D38: 56.362304 | E38: 62.45 | F38: =D38-E38 -> -6.0876959 | G38: Overcharged
B46: Accident Year | C46: Earned Premiums | D46: Indicative Loss Ratio(Percentage) | E46: Target Loss Ratio%(Average ) | F46: Difference(Points) | G46: Rate Adequacy Verdict
B47: 2016 | C47: 11336988 | D47: 71.496318 | E47: 72.36 | F47: =D47-E47 -> -0.86368193 | G47: Roughly Adequate
B48: 2017 | C48: 11837624 | D48: 66.733175 | E48: 72.36 | F48: =D48-E48 -> -5.626825 | G48: Overcharged
B49: 2018 | C49: 12381799 | D49: 67.096253 | E49: 72.36 | F49: =D49-E49 -> -5.2637467 | G49: Overcharged
B50: 2019 | C50: 12827570 | D50: 70.25042 | E50: 72.36 | F50: =D50-E50 -> -2.1095801 | G50: Roughly Adequate
B51: 2020 | C51: 12336855 | D51: 59.222851 | E51: 72.36 | F51: =D51-E51 -> -13.137149 | G51: Overcharged
B52: 2021 | C52: 13449965 | D52: 75.492563 | E52: 72.36 | F52: =D52-E52 -> 3.1325626 | G52: Roughly Adequate
B53: 2022 | C53: 14619643 | D53: 82.894135 | E53: 72.36 | F53: =D53-E53 -> 10.534135 | G53: Undercharged
B54: 2023 | C54: 16660394 | D54: 80.418498 | E54: 72.36 | F54: =D54-E54 -> 8.0584979 | G54: Undercharged
B55: 2024 | C55: 18993672 | D55: 72.828589 | E55: 72.36 | F55: =D55-E55 -> 0.46858872 | G55: Roughly Adequate
B56: 2025 | C56: 20474091 | D56: 71.962116 | E56: 72.36 | F56: =D56-E56 -> -0.39788384 | G56: Roughly Adequate
B64: Accident Year | C64: Earned Premiums | D64: Indicative Loss Ratio(Percentage) | E64: Target Loss Ratio%(Average ) | F64: Difference(Points) | G64: Rate Adequacy Verdict
B65: 2016 | C65: 255426 | D65: 92.876215 | E65: 103.83 | F65: =D65-E65 -> -10.953785 | G65: Overcharged
B66: 2017 | C66: 260211 | D66: 76.285255 | E66: 103.83 | F66: =D66-E66 -> -27.544745 | G66: Overcharged
B67: 2018 | C67: 360958 | D67: 79.164917 | E67: 103.83 | F67: =D67-E67 -> -24.665083 | G67: Overcharged
B68: 2019 | C68: 540525 | D68: 89.583866 | E68: 103.83 | F68: =D68-E68 -> -14.246134 | G68: Overcharged
B69: 2020 | C69: 464213 | D69: 87.384645 | E69: 103.83 | F69: =D69-E69 -> -16.445355 | G69: Overcharged
B70: 2021 | C70: 658255 | D70: 122.55312 | E70: 103.83 | F70: =D70-E70 -> 18.723124 | G70: Undercharged
...
