Workbook

Sheet Loss Development Triangles
B6: Combined Cumulative Net Losses Across All Business
B8: Years in which losses where incurred | C8: 0 | D8: 1 | E8: 2 | F8: 3 | G8: 4 | H8: 5 | I8: 6 | J8: 7 | K8: 8 | L8: 9
B9: 2016 | C9: 7964946 | D9: 11241095 | E9: 13257988 | F9: 14688022 | G9: 15458491 | H9: 15962513 | I9: 16386278 | J9: 16606627 | K9: 16825042 | L9: 16930457
B10: 2017 | C10: 8618133 | D10: 13151813 | E10: 15225336 | F10: 16352926 | G10: 17458322 | H10: 18197608 | I10: 18712239 | J10: 19057962 | K10: 19282126 | L10: 0
B11: 2018 | C11: 9145166 | D11: 13760904 | E11: 15726441 | F11: 17194799 | G11: 18409660 | H11: 19226690 | I11: 19772597 | J11: 20057256 | K11: 0 | L11: 0
B12: 2019 | C12: 9582716 | D12: 13549187 | E12: 15775684 | F12: 17451029 | G12: 18628084 | H12: 19475321 | I12: 20076247 | J12: 0 | K12: 0 | L12: 0
B13: 2020 | C13: 8890414 | D13: 12727542 | E13: 14507599 | F13: 15905843 | G13: 16881346 | H13: 17700445 | I13: 0 | J13: 0 | K13: 0 | L13: 0
B14: 2021 | C14: 10145792 | D14: 14969273 | E14: 17144340 | F14: 18656299 | G14: 19547276 | H14: 0 | I14: 0 | J14: 0 | K14: 0 | L14: 0
B15: 2022 | C15: 11236402 | D15: 17635295 | E15: 20206175 | F15: 21757828 | G15: 0 | H15: 0 | I15: 0 | J15: 0 | K15: 0 | L15: 0
B16: 2023 | C16: 12732411 | D16: 18531516 | E16: 20987296 | F16: 0 | G16: 0 | H16: 0 | I16: 0 | J16: 0 | K16: 0 | L16: 0
B17: 2024 | C17: 9959683 | D17: 14658662 | E17: 0 | F17: 0 | G17: 0 | H17: 0 | I17: 0 | J17: 0 | K17: 0 | L17: 0
B18: 2025 | C18: 8433068 | D18: 0 | E18: 0 | F18: 0 | G18: 0 | H18: 0 | I18: 0 | J18: 0 | K18: 0 | L18: 0
B26: Cumulative Net losses For Homeowners and Farmowners
B28: Years in which losses where incurred | C28: 0 | D28: 1 | E28: 2 | F28: 3 | G28: 4 | H28: 5 | I28: 6 | J28: 7 | K28: 8 | L28: 9
B29: 2016 | C29: 2423845 | D29: 3091246 | E29: 3211023 | F29: 3264217 | G29: 3286436 | H29: 3296712 | I29: 3303156 | J29: 3310486 | K29: 3318809 | L29: 3321354
B30: 2017 | C30: 2870888 | D30: 3633255 | E30: 3856307 | F30: 3752149 | G30: 3789187 | H30: 3803008 | I30: 3809519 | J30: 3817286 | K30: 3820003 | L30: 0
B31: 2018 | C31: 2620286 | D31: 3502130 | E31: 3597539 | F31: 3649075 | G31: 3685401 | H31: 3706398 | I31: 3717877 | J31: 3721713 | K31: 0 | L31: 0
B32: 2019 | C32: 2671576 | D32: 3554709 | E32: 3725461 | F32: 3789792 | G32: 3834923 | H32: 3857832 | I32: 3866451 | J32: 0 | K32: 0 | L32: 0
B33: 2020 | C33: 3010217 | D33: 4101536 | E33: 4308749 | F33: 4402119 | G33: 4444123 | H33: 4460628 | I33: 0 | J33: 0 | K33: 0 | L33: 0
B34: 2021 | C34: 3746198 | D34: 5158177 | E34: 5332074 | F34: 5411191 | G34: 5444061 | H34: 0 | I34: 0 | J34: 0 | K34: 0 | L34: 0
B35: 2022 | C35: 3523779 | D35: 5210673 | E35: 5467954 | F35: 5559443 | G35: 0 | H35: 0 | I35: 0 | J35: 0 | K35: 0 | L35: 0
B36: 2023 | C36: 4630317 | D36: 6223329 | E36: 6505882 | F36: 0 | G36: 0 | H36: 0 | I36: 0 | J36: 0 | K36: 0 | L36: 0
B37: 2024 | C37: 3558853 | D37: 4830559 | E37: 0 | F37: 0 | G37: 0 | H37: 0 | I37: 0 | J37: 0 | K37: 0 | L37: 0
B38: 2025 | C38: 3401457 | D38: 0 | E38: 0 | F38: 0 | G38: 0 | H38: 0 | I38: 0 | J38: 0 | K38: 0 | L38: 0
B44: Cumulative Net losses For PRIVATE PASSENGER AUTO LIABILITY/MEDICAL
B46: Years in which losses where incurred | C46: 0 | D46: 1 | E46: 2 | F46: 3 | G46: 4 | H46: 5 | I46: 6 | J46: 7 | K46: 8 | L46: 9
B47: 2016 | C47: 1665096 | D47: 3019298 | E47: 3761891 | F47: 4244638 | G47: 4469729 | H47: 4594118 | I47: 4672661 | J47: 4706971 | K47: 4731272 | L47: 4737279
B48: 2017 | C48: 1658881 | D48: 3030214 | E48: 3739995 | F48: 4152308 | G48: 4429615 | H48: 4599778 | I48: 4677407 | J48: 4710523 | K48: 4717707 | L48: 0
B49: 2018 | C49: 1631008 | D49: 3004977 | E49: 3689877 | F49: 4167167 | G49: 4468749 | H49: 4629166 | I49: 4717380 | J49: 4735270 | K49: 0 | L49: 0
B50: 2019 | C50: 1634420 | D50: 2900718 | E50: 3622492 | F50: 4130626 | G50: 4452611 | H50: 4590971 | I50: 4640838 | J50: 0 | K50: 0 | L50: 0
B51: 2020 | C51: 1262753 | D51: 2336814 | E51: 2945538 | F51: 3371223 | G51: 3564490 | H51: 3636672 | I51: 0 | J51: 0 | K51: 0 | L51: 0
B52: 2021 | C52: 1558964 | D52: 3111483 | E52: 3994070 | F52: 4468657 | G52: 4674585 | H52: 0 | I52: 0 | J52: 0 | K52: 0 | L52: 0
B53: 2022 | C53: 1949133 | D53: 3839271 | E53: 4758065 | F53: 5218593 | H53: 0 | I53: 0 | J53: 0 | K53: 0 | L53: 0
B54: 2023 | C54: 1870969 | D54: 3569997 | E54: 4418368 | F54: 0 | G54: 0 | H54: 0 | I54: 0 | J54: 0 | K54: 0 | L54: 0
B55: 2024 | C55: 1563421 | D55: 2908115 | E55: 0 | F55: 0 | G55: 0 | H55: 0 | I55: 0 | J55: 0 | K55: 0 | L55: 0
B56: 2025 | C56: 1180595 | D56: 0 | E56: 0 | F56: 0 | G56: 0 | H56: 0 | I56: 0 | J56: 0 | K56: 0 | L56: 0
B62: Cumulative Net losses For COMMERCIAL AUTO/TRUCK LIABILITY/MEDICAL
B64: Years in which losses where incurred | C64: 0 | D64: 1 | E64: 2 | F64: 3 | G64: 4 | H64: 5 | I64: 6 | J64: 7 | K64: 8 | L64: 9
B65: 2016 | C65: 181551 | D65: 439630 | E65: 720054 | F65: 949065 | G65: 1058473 | H65: 1107963 | I65: 1146391 | J65: 1165788 | K65: 1172562 | L65: 1174894
B66: 2017 | C66: 197593 | D66: 475939 | E66: 735503 | F66: 915383 | G66: 1039547 | H66: 1133959 | I66: 1190862 | J66: 1209299 | K66: 1217856 | L66: 0
...

Sheet year to ultimate LDF
C8: Volume weighted loss development factor | E8: Year to ultimate loss development factor
C9: f1 | D9: =SUM('Loss Development Triangles'!D9:D17)/SUM('Loss Development Triangles'!C9:C17) -> 1.4752117 | E9: 1 to ultimate | F9: =PRODUCT(D9:D17) -> 2.1784187
C10: f2 | D10: =SUM('Loss Development Triangles'!E9:E16)/SUM('Loss Development Triangles'!D9:D16) -> 1.1493877 | E10: 2 to ultimate | F10: =PRODUCT(D10:D17) -> 1.4766822
C11: f3 | D11: =SUM('Loss Development Triangles'!F9:F15)/SUM('Loss Development Triangles'!E9:E15) -> 1.0908696 | E11: 3 to ultimate | F11: =PRODUCT(D11:D17) -> 1.2847555
C12: f4 | D12: =SUM('Loss Development Triangles'!G9:G14)/SUM('Loss Development Triangles'!F9:F14) -> 1.0611903 | E12: 4 to ultimate | F12: =PRODUCT(D12:D17) -> 1.1777351
C13: f5 | D13: =SUM('Loss Development Triangles'!H9:H13)/SUM('Loss Development Triangles'!G9:G13) -> 1.0429163 | E13: 5 to ultimate | F13: =PRODUCT(D13:D17) -> 1.1098246
C14: f6 | D14: =SUM('Loss Development Triangles'!I9:I12)/SUM('Loss Development Triangles'!H9:H12) -> 1.0286188 | E14: 6 to ultimate | F14: =PRODUCT(D14:D17) -> 1.064155
C15: f7 | D15: =SUM('Loss Development Triangles'!J9:J11)/SUM('Loss Development Triangles'!I9:I11) -> 1.0155042 | E15: 7 to ultimate | F15: =PRODUCT(D15:D17) -> 1.0345475
C16: f8 | D16: =SUM('Loss Development Triangles'!K9:K10)/SUM('Loss Development Triangles'!J9:J10) -> 1.0124095 | E16: 8 to ultimate | F16: =PRODUCT(D16:D17) -> 1.0187526
C17: f9 | D17: =SUM('Loss Development Triangles'!L9)/SUM('Loss Development Triangles'!K9) -> 1.0062654 | E17: 9 to ultimate | F17: =PRODUCT(D17) -> 1.0062654
C18: f10 | D18: 1 | E18: 10 to ultimate | F18: 1
C28: Volume weighted loss development factor | E28: Year to ultimate loss development factor
C29: f1 | D29: =SUM('Loss Development Triangles'!D29:D37)/SUM('Loss Development Triangles'!C29:C37) -> 1.3527557 | E29: 1 to ultimate | F29: =PRODUCT(D29:D37) -> 1.456793
C30: f2 | D30: =SUM('Loss Development Triangles'!E29:E36)/SUM('Loss Development Triangles'!D29:D36) -> 1.044378 | E30: 2 to ultimate | F30: =PRODUCT(D30:D37) -> 1.0769077
C31: f3 | D31: =SUM('Loss Development Triangles'!F29:F35)/SUM('Loss Development Triangles'!E29:E35) -> 1.0111488 | E31: 3 to ultimate | F31: =PRODUCT(D31:D37) -> 1.0311474
C32: f4 | D32: =SUM('Loss Development Triangles'!G29:G34)/SUM('Loss Development Triangles'!F29:F34) -> 1.0088834 | E32: 4 to ultimate | F32: =PRODUCT(D32:D37) -> 1.0197782
C33: f5 | D33: =SUM('Loss Development Triangles'!H29:H33)/SUM('Loss Development Triangles'!G29:G33) -> 1.0044384 | E33: 5 to ultimate | F33: =PRODUCT(D33:D37) -> 1.0107988
C34: f6 | D34: =SUM('Loss Development Triangles'!I29:I32)/SUM('Loss Development Triangles'!H29:H32) -> 1.002254 | E34: 6 to ultimate | F34: =PRODUCT(D34:D37) -> 1.0063323
C35: f7 | D35: =SUM('Loss Development Triangles'!J29:J31)/SUM('Loss Development Triangles'!I29:I31) -> 1.0017481 | E35: 7 to ultimate | F35: =PRODUCT(D35:D37) -> 1.0040691
C36: f8 | D36: =SUM('Loss Development Triangles'!K29:K30)/SUM('Loss Development Triangles'!J29:J30) -> 1.0015489 | E36: 8 to ultimate | F36: =PRODUCT(D36:D37) -> 1.0023169
C37: f9 | D37: =SUM('Loss Development Triangles'!L29)/SUM('Loss Development Triangles'!K29) -> 1.0007668 | E37: 9 to ultimate | F37: =PRODUCT(D37) -> 1.0007668
C38: f10 | D38: 1 | E38: 10 to ultimate | F38: 1
C46: Volume weighted loss development factor | E46: Year to ultimate loss development factor
C47: f1 | D47: =SUM('Loss Development Triangles'!D47:D55)/SUM('Loss Development Triangles'!C47:C55) -> 1.8737109 | E47: 1 to ultimate | F47: =PRODUCT(D47:D55) -> 2.9479235
C48: f2 | D48: =SUM('Loss Development Triangles'!E47:E54)/SUM('Loss Development Triangles'!D47:D54) -> 1.2465474 | E48: 2 to ultimate | F48: =PRODUCT(D48:D55) -> 1.5733076
C49: f3 | D49: =SUM('Loss Development Triangles'!F47:F53)/SUM('Loss Development Triangles'!E47:E53) -> 1.1222576 | E49: 3 to ultimate | F49: =PRODUCT(D49:D55) -> 1.2621322
C50: f4 | D50: =SUM('Loss Development Triangles'!G47:G52)/SUM('Loss Development Triangles'!F47:F52) -> 1.0621636 | E50: 4 to ultimate | F50: =PRODUCT(D50:D55) -> 1.1246368
C51: f5 | D51: =SUM('Loss Development Triangles'!H47:H51)/SUM('Loss Development Triangles'!G47:G51) -> 1.0311202 | E51: 5 to ultimate | F51: =PRODUCT(D51:D55) -> 1.058817
C52: f6 | D52: =SUM('Loss Development Triangles'!I47:I50)/SUM('Loss Development Triangles'!H47:H50) -> 1.0159798 | E52: 6 to ultimate | F52: =PRODUCT(D52:D55) -> 1.0268609
C53: f7 | D53: =SUM('Loss Development Triangles'!J47:J49)/SUM('Loss Development Triangles'!I47:I49) -> 1.0060648 | E53: 7 to ultimate | F53: =PRODUCT(D53:D55) -> 1.0107099
C54: f8 | D54: =SUM('Loss Development Triangles'!K47:K48)/SUM('Loss Development Triangles'!J47:J48) -> 1.0033432 | E54: 8 to ultimate | F54: =PRODUCT(D54:D55) -> 1.0046171
C55: f9 | D55: =SUM('Loss Development Triangles'!L47)/SUM('Loss Development Triangles'!K47) -> 1.0012696 | E55: 9 to ultimate | F55: =PRODUCT(D55) -> 1.0012696
C56: f10 | D56: 1 | E56: 10 to ultimate | F56: 1
C64: Volume weighted loss development factor | E64: Year to ultimate loss development factor
C65: f1 | D65: =SUM('Loss Development Triangles'!D65:D73)/SUM('Loss Development Triangles'!C65:C73) -> 2.4760255 | E65: 1 to ultimate | F65: =PRODUCT(D65:D73) -> 7.0887804
C66: f2 | D66: =SUM('Loss Development Triangles'!E65:E72)/SUM('Loss Development Triangles'!D65:D72) -> 1.6032747 | E66: 2 to ultimate | F66: =PRODUCT(D66:D73) -> 2.8629674
C67: f3 | D67: =SUM('Loss Development Triangles'!F65:F71)/SUM('Loss Development Triangles'!E65:E71) -> 1.3186093 | E67: 3 to ultimate | F67: =PRODUCT(D67:D73) -> 1.7856998
C68: f4 | D68: =SUM('Loss Development Triangles'!G65:G70)/SUM('Loss Development Triangles'!F65:F70) -> 1.1775131 | E68: 4 to ultimate | F68: =PRODUCT(D68:D73) -> 1.3542296
C69: f5 | D69: =SUM('Loss Development Triangles'!H65:H69)/SUM('Loss Development Triangles'!G65:G69) -> 1.079394 | E69: 5 to ultimate | F69: =PRODUCT(D69:D73) -> 1.1500761
C70: f6 | D70: =SUM('Loss Development Triangles'!I65:I68)/SUM('Loss Development Triangles'!H65:H68) -> 1.0388621 | E70: 6 to ultimate | F70: =PRODUCT(D70:D73) -> 1.0654831
...

Sheet loss reserve and loss ratio
C8: Accident Year | D8: Cumulative paid loss to date | E8: Age at latest evaluation | F8: Ultimate Loss development Factor | G8: Expected Loss(Chain Ladder Method) | H8: Loss Reserves(Chain Ladder Method) | I8: Earned Premiums | J8: Expected Loss Ratio
C9: 2016 | D9: 16930457 | E9: 9 | F9: 1 | G9: =PRODUCT(D9,F9) -> 16930457 | H9: =G9-D9 -> 0 | I9: 27962781 | J9: =(G9/I9)*100 -> 60.546399
C10: 2017 | D10: 19282126 | E10: 8 | F10: 1.0062654 | G10: =PRODUCT(D10,F10) -> 19402936 | H10: =G10-D10 -> 120809.52 | I10: 29548681 | J10: =(G10/I10)*100 -> 65.664303
C11: 2018 | D11: 20057256 | E11: 7 | F11: 1.0187526 | G11: =PRODUCT(D11,F11) -> 20433382 | H11: =G11-D11 -> 376125.56 | I11: 32980754 | J11: =(G11/I11)*100 -> 61.955471
C12: 2019 | D12: 20076247 | E12: 6 | F12: 1.0345475 | G12: =PRODUCT(D12,F12) -> 20769831 | H12: =G12-D12 -> 693584.24 | I12: 33877643 | J12: =(G12/I12)*100 -> 61.308372
C13: 2020 | D13: 17700445 | E13: 5 | F13: 1.064155 | G13: =PRODUCT(D13,F13) -> 18836018 | H13: =G13-D13 -> 1135572.8 | I13: 33865530 | J13: =(G13/I13)*100 -> 55.62003
C14: 2021 | D14: 19547276 | E14: 4 | F14: 1.1098246 | G14: =PRODUCT(D14,F14) -> 21694048 | H14: =G14-D14 -> 2146772.2 | I14: 34694312 | J14: =(G14/I14)*100 -> 62.529121
C15: 2022 | D15: 21757828 | E15: 3 | F15: 1.1777351 | G15: =PRODUCT(D15,F15) -> 25624958 | H15: =G15-D15 -> 3867130.1 | I15: 39110525 | J15: =(G15/I15)*100 -> 65.519341
C16: 2023 | D16: 20987296 | E16: 2 | F16: 1.2847555 | G16: =PRODUCT(D16,F16) -> 26963543 | H16: =G16-D16 -> 5976247.4 | I16: 40164363 | J16: =(G16/I16)*100 -> 67.133004
C17: 2024 | D17: 14658662 | E17: 1 | F17: 1.4766822 | G17: =PRODUCT(D17,F17) -> 21646185 | H17: =G17-D17 -> 6987522.6 | I17: 39257768 | J17: =(G17/I17)*100 -> 55.138602
C18: 2025 | D18: 8433068 | E18: 0 | F18: 2.1784187 | G18: =PRODUCT(D18,F18) -> 18370753 | H18: =G18-D18 -> 9937685.3 | I18: 38003928 | J18: =(G18/I18)*100 -> 48.339091
F19: Total | G19: =SUM(G9:G18) -> 2.1067211e+08 | H19: =SUM(H9:H18) -> 31241450 | I19: =SUM(I9:I18) -> 349466285 | J19: =(G19/I19)*100 -> 60.283959
C28: Accident Year | D28: Cumulative paid loss to date | E28: Age at latest evaluation | F28: Ultimate Loss development Factor | G28: Expected Loss(Chain Ladder Method) | H28: Loss Reserves(Chain Ladder Method) | I28: Earned Premiums | J28: Expected Loss Ratio
C29: 2016 | D29: 3321354 | E29: 9 | F29: 1 | G29: =PRODUCT(D29,F29) -> 3321354 | H29: =G29-D29 -> 0 | I29: 6199941 | J29: =(G29/I29)*100 -> 53.570736
C30: 2017 | D30: 3820003 | E30: 8 | F30: 1.0007668 | G30: =PRODUCT(D30,F30) -> 3822932.3 | H30: =G30-D30 -> 2929.3363 | I30: 6345477 | J30: =(G30/I30)*100 -> 60.246571
C31: 2018 | D31: 3721713 | E31: 7 | F31: 1.0023169 | G31: =PRODUCT(D31,F31) -> 3730335.8 | H31: =G31-D31 -> 8622.8375 | I31: 6654376 | J31: =(G31/I31)*100 -> 56.058387
C32: 2019 | D32: 3866451 | E32: 6 | F32: 1.0040691 | G32: =PRODUCT(D32,F32) -> 3882183.8 | H32: =G32-D32 -> 15732.824 | I32: 6874401 | J32: =(G32/I32)*100 -> 56.473049
C33: 2020 | D33: 4460628 | E33: 5 | F33: 1.0063323 | G33: =PRODUCT(D33,F33) -> 4488873.9 | H33: =G33-D33 -> 28245.873 | I33: 7099380 | J33: =(G33/I33)*100 -> 63.229097
C34: 2021 | D34: 5444061 | E34: 4 | F34: 1.0107988 | G34: =PRODUCT(D34,F34) -> 5502850.3 | H34: =G34-D34 -> 58789.315 | I34: 7701233 | J34: =(G34/I34)*100 -> 71.454147
C35: 2022 | D35: 5559443 | E35: 3 | F35: 1.0197782 | G35: =PRODUCT(D35,F35) -> 5669398.6 | H35: =G35-D35 -> 109955.57 | I35: 8512807 | J35: =(G35/I35)*100 -> 66.598462
C36: 2023 | D36: 6505882 | E36: 2 | F36: 1.0311474 | G36: =PRODUCT(D36,F36) -> 6708523.6 | H36: =G36-D36 -> 202641.59 | I36: 9279834 | J36: =(G36/I36)*100 -> 72.291418
C37: 2024 | D37: 4830559 | E37: 1 | F37: 1.0769077 | G37: =PRODUCT(D37,F37) -> 5202066.2 | H37: =G37-D37 -> 371507.2 | I37: 10193824 | J37: =(G37/I37)*100 -> 51.031548
C38: 2025 | D38: 3401457 | E38: 0 | F38: 1.456793 | G38: =PRODUCT(D38,F38) -> 4955218.8 | H38: =G38-D38 -> 1553761.8 | I38: 10452012 | J38: =(G38/I38)*100 -> 47.409234
F39: Total | G39: =SUM(G29:G38) -> 47283737 | H39: =SUM(H29:H38) -> 2352186.4 | I39: =SUM(I29:I38) -> 79313285 | J39: =(G39/I39)*100 -> 59.616415
C46: Accident Year | D46: Cumulative paid loss to date | E46: Age at latest evaluation | F46: Ultimate Loss development Factor | G46: Expected Loss(Chain Ladder Method) | H46: Loss Reserves(Chain Ladder Method) | I46: Earned Premiums | J46: Expected Loss Ratio
C47: 2016 | D47: 4737279 | E47: 9 | F47: 1 | G47: =PRODUCT(D47,F47) -> 4737279 | H47: =G47-D47 -> 0 | I47: 6267801 | J47: =(G47/I47)*100 -> 75.581197
C48: 2017 | D48: 4717707 | E48: 8 | F48: 1.0012696 | G48: =PRODUCT(D48,F48) -> 4723696.8 | H48: =G48-D48 -> 5989.7774 | I48: 6689561 | J48: =(G48/I48)*100 -> 70.612956
C49: 2018 | D49: 4735270 | E49: 7 | F49: 1.0046171 | G49: =PRODUCT(D49,F49) -> 4757133.3 | H49: =G49-D49 -> 21863.349 | I49: 7094989 | J49: =(G49/I49)*100 -> 67.0492
C50: 2019 | D50: 4640838 | E50: 6 | F50: 1.0107099 | G50: =PRODUCT(D50,F50) -> 4690541 | H50: =G50-D50 -> 49702.965 | I50: 7103034 | J50: =(G50/I50)*100 -> 66.035739
C51: 2020 | D51: 3636672 | E51: 5 | F51: 1.0268609 | G51: =PRODUCT(D51,F51) -> 3734356.2 | H51: =G51-D51 -> 97684.202 | I51: 6954739 | J51: =(G51/I51)*100 -> 53.695131
C52: 2021 | D52: 4674585 | E52: 4 | F52: 1.058817 | G52: =PRODUCT(D52,F52) -> 4949529.9 | H52: =G52-D52 -> 274944.92 | I52: 7368884 | J52: =(G52/I52)*100 -> 67.167972
C53: 2022 | D53: 5218593 | E53: 3 | F53: 1.1246368 | G53: =PRODUCT(D53,F53) -> 5869021.9 | H53: =G53-D53 -> 650428.91 | I53: 7845430 | J53: =(G53/I53)*100 -> 74.808161
C54: 2023 | D54: 4418368 | E54: 2 | F54: 1.2621322 | G54: =PRODUCT(D54,F54) -> 5576564.5 | H54: =G54-D54 -> 1158196.5 | I54: 7487936 | J54: =(G54/I54)*100 -> 74.473988
C55: 2024 | D55: 2908115 | E55: 1 | F55: 1.5733076 | G55: =PRODUCT(D55,F55) -> 4575359.4 | H55: =G55-D55 -> 1667244.4 | I55: 6887581 | J55: =(G55/I55)*100 -> 66.42912
C56: 2025 | D56: 1180595 | E56: 0 | F56: 2.9479235 | G56: =PRODUCT(D56,F56) -> 3480303.8 | H56: =G56-D56 -> 2299708.8 | I56: 6186321 | J56: =(G56/I56)*100 -> 56.258053
F57: Total | G57: =SUM(G47:G56) -> 47093786 | H57: =SUM(H47:H56) -> 6225763.9 | I57: =SUM(I47:I56) -> 69886276 | J57: =(G57/I57)*100 -> 67.386315
C64: Accident Year | D64: Cumulative paid loss to date | E64: Age at latest evaluation | F64: Ultimate Loss development Factor | G64: Expected Loss(Chain Ladder Method) | H64: Loss Reserves(Chain Ladder Method) | I64: Earned Premiums | J64: Expected Loss Ratio
C65: 2016 | D65: 1174894 | E65: 9 | F65: 1 | G65: =PRODUCT(D65,F65) -> 1174894 | H65: =G65-D65 -> 0 | I65: 1425900 | J65: =(G65/I65)*100 -> 82.396662
C66: 2017 | D66: 1217856 | E66: 8 | F66: 1.0019888 | G66: =PRODUCT(D66,F66) -> 1220278.1 | H66: =G66-D66 -> 2422.081 | I66: 1515575 | J66: =(G66/I66)*100 -> 80.515849
C67: 2018 | D67: 1208500 | E67: 7 | F67: 1.0084566 | G67: =PRODUCT(D67,F67) -> 1218719.8 | H67: =G67-D67 -> 10219.761 | I67: 1511812 | J67: =(G67/I67)*100 -> 80.613182
...

Sheet rate adequacy verdict
B8: Accident Year | C8: Earned Premiums | D8: Indicative Loss Ratio(Percentage) | E8: Target Loss Ratio%(Average ) | F8: Difference(Points) | G8: Rate Adequacy Verdict
B9: 2016 | C9: 27962781 | D9: 60.546399 | E9: 60.28 | F9: =D9-E9 -> 0.26639916 | G9: Roughly Adequate
B10: 2017 | C10: 29548681 | D10: 65.664303 | E10: 60.28 | F10: =D10-E10 -> 5.3843033 | G10: Undercharged
B11: 2018 | C11: 32980754 | D11: 61.955471 | E11: 60.28 | F11: =D11-E11 -> 1.6754712 | G11: Roughly Adequate
B12: 2019 | C12: 33877643 | D12: 61.308372 | E12: 60.28 | F12: =D12-E12 -> 1.0283716 | G12: Roughly Adequate
B13: 2020 | C13: 33865530 | D13: 55.62003 | E13: 60.28 | F13: =D13-E13 -> -4.6599703 | G13: Roughly Adequate
B14: 2021 | C14: 34694312 | D14: 62.529121 | E14: 60.28 | F14: =D14-E14 -> 2.2491206 | G14: Roughly Adequate
B15: 2022 | C15: 39110525 | D15: 65.519341 | E15: 60.28 | F15: =D15-E15 -> 5.2393408 | G15: Undercharged
B16: 2023 | C16: 40164363 | D16: 67.133004 | E16: 60.28 | F16: =D16-E16 -> 6.8530039 | G16: Undercharged
B17: 2024 | C17: 39257768 | D17: 55.138602 | E17: 60.28 | F17: =D17-E17 -> -5.1413976 | G17: Overcharged
B18: 2025 | C18: 38003928 | D18: 48.339091 | E18: 60.28 | F18: =D18-E18 -> -11.940909 | G18: Overcharged
B28: Accident Year | C28: Earned Premiums | D28: Indicative Loss Ratio(Percentage) | E28: Target Loss Ratio%(Average ) | F28: Difference(Points) | G28: Rate Adequacy Verdict
B29: 2016 | C29: 6199941 | D29: 53.570736 | E29: 59.62 | F29: =D29-E29 -> -6.0492644 | G29: Overcharged
B30: 2017 | C30: 6345477 | D30: 60.246571 | E30: 59.62 | F30: =D30-E30 -> 0.62657148 | G30: Roughly Adequate
B31: 2018 | C31: 6654376 | D31: 56.058387 | E31: 59.62 | F31: =D31-E31 -> -3.5616132 | G31: Roughly Adequate
B32: 2019 | C32: 6874401 | D32: 56.473049 | E32: 59.62 | F32: =D32-E32 -> -3.1469513 | G32: Roughly Adequate
B33: 2020 | C33: 7099380 | D33: 63.229097 | E33: 59.62 | F33: =D33-E33 -> 3.6090971 | G33: Roughly Adequate
B34: 2021 | C34: 7701233 | D34: 71.454147 | E34: 59.62 | F34: =D34-E34 -> 11.834147 | G34: Undercharged
B35: 2022 | C35: 8512807 | D35: 66.598462 | E35: 59.62 | F35: =D35-E35 -> 6.9784624 | G35: Undercharged
B36: 2023 | C36: 9279834 | D36: 72.291418 | E36: 59.62 | F36: =D36-E36 -> 12.671418 | G36: Undercharged
B37: 2024 | C37: 10193824 | D37: 51.031548 | E37: 59.62 | F37: =D37-E37 -> -8.5884518 | G37: Overcharged
B38: 2025 | C38: 10452012 | D38: 47.409234 | E38: 59.62 | F38: =D38-E38 -> -12.210766 | G38: Overcharged
B46: Accident Year | C46: Earned Premiums | D46: Indicative Loss Ratio(Percentage) | E46: Target Loss Ratio%(Average ) | F46: Difference(Points) | G46: Rate Adequacy Verdict
B47: 2016 | C47: 6267801 | D47: 75.581197 | E47: 67.386315 | F47: =D47-E47 -> 8.194882 | G47: Undercharged
B48: 2017 | C48: 6689561 | D48: 70.612956 | E48: 67.386315 | F48: =D48-E48 -> 3.2266415 | G48: Roughly Adequate
B49: 2018 | C49: 7094989 | D49: 67.0492 | E49: 67.386315 | F49: =D49-E49 -> -0.3371149 | G49: Roughly Adequate
B50: 2019 | C50: 7103034 | D50: 66.035739 | E50: 67.386315 | F50: =D50-E50 -> -1.3505761 | G50: Roughly Adequate
B51: 2020 | C51: 6954739 | D51: 53.695131 | E51: 67.386315 | F51: =D51-E51 -> -13.691184 | G51: Overcharged
B52: 2021 | C52: 7368884 | D52: 67.167972 | E52: 67.386315 | F52: =D52-E52 -> -0.21834295 | G52: Roughly Adequate
B53: 2022 | C53: 7845430 | D53: 74.808161 | E53: 67.386315 | F53: =D53-E53 -> 7.4218463 | G53: Undercharged
B54: 2023 | C54: 7487936 | D54: 74.473988 | E54: 67.386315 | F54: =D54-E54 -> 7.0876731 | G54: Undercharged
B55: 2024 | C55: 6887581 | D55: 66.42912 | E55: 67.386315 | F55: =D55-E55 -> -0.95719509 | G55: Roughly Adequate
B56: 2025 | C56: 6186321 | D56: 56.258053 | E56: 67.386315 | F56: =D56-E56 -> -11.128261 | G56: Overcharged
B64: Accident Year | C64: Earned Premiums | D64: Indicative Loss Ratio(Percentage) | E64: Target Loss Ratio%(Average ) | F64: Difference(Points) | G64: Rate Adequacy Verdict
B65: 2016 | C65: 1425900 | D65: 82.396662 | E65: 72.639307 | F65: =D65-E65 -> 9.7573544 | G65: Undercharged
B66: 2017 | C66: 1515575 | D66: 80.515849 | E66: 72.639307 | F66: =D66-E66 -> 7.8765419 | G66: Undercharged
B67: 2018 | C67: 1511812 | D67: 80.613182 | E67: 72.639307 | F67: =D67-E67 -> 7.9738748 | G67: Undercharged
B68: 2019 | C68: 1548861 | D68: 77.043812 | E68: 72.639307 | F68: =D68-E68 -> 4.4045048 | G68: Roughly Adequate
B69: 2020 | C69: 1506500 | D69: 60.337463 | E69: 72.639307 | F69: =D69-E69 -> -12.301844 | G69: Overcharged
B70: 2021 | C70: 1534073 | D70: 69.038168 | E70: 72.639307 | F70: =D70-E70 -> -3.6011398 | G70: Roughly Adequate
...
