Workbook

Sheet Loss Development
B6: Combined Cumulative Net Losses Across All Business
B8: Years in which losses where incurred | C8: 0 | D8: 1 | E8: 2 | F8: 3 | G8: 4 | H8: 5 | I8: 6 | J8: 7 | K8: 8 | L8: 9
B9: 2016 | C9: 4826862 | D9: 7588442 | E9: 9039686 | F9: 10109878 | G9: 10724693 | H9: 11143668 | I9: 11435279 | J9: 11579740 | K9: 11706649 | L9: 11798741
B10: 2017 | C10: 5967716 | D10: 9332252 | E10: 10987843 | F10: 11853392 | G10: 12594782 | H10: 13154074 | I10: 13504163 | J10: 13726261 | K10: 13870301 | L10: 0
B11: 2018 | C11: 6246413 | D11: 9836031 | E11: 11334472 | F11: 12469518 | G11: 13371800 | H11: 13975048 | I11: 14371819 | J11: 14589305 | K11: 0 | L11: 0
B12: 2019 | C12: 6262380 | D12: 9839107 | E12: 11593201 | F12: 12987689 | G12: 14007891 | H12: 14635580 | I12: 14995725 | J12: 0 | K12: 0 | L12: 0
B13: 2020 | C13: 6198958 | D13: 9276611 | E13: 10804698 | F13: 12059085 | G13: 12945691 | H13: 13452890 | I13: 0 | J13: 0 | K13: 0 | L13: 0
B14: 2021 | C14: 7071516 | D14: 11030361 | E14: 12797687 | F14: 14115345 | G14: 15019191 | H14: 0 | I14: 0 | J14: 0 | K14: 0 | L14: 0
B15: 2022 | C15: 7960697 | D15: 13022813 | E15: 15269999 | F15: 16753459 | G15: 0 | H15: 0 | I15: 0 | J15: 0 | K15: 0 | L15: 0
B16: 2023 | C16: 9315380 | D16: 14459469 | E16: 16790693 | F16: 0 | G16: 0 | H16: 0 | I16: 0 | J16: 0 | K16: 0 | L16: 0
B17: 2024 | C17: 9325572 | D17: 14226152 | E17: 0 | F17: 0 | G17: 0 | H17: 0 | I17: 0 | J17: 0 | K17: 0 | L17: 0
B18: 2025 | C18: 8975277 | D18: 0 | E18: 0 | F18: 0 | G18: 0 | H18: 0 | I18: 0 | J18: 0 | K18: 0 | L18: 0
B26: Cumulative Net losses For Homeowners and Farmowners
B28: Years in which losses where incurred | C28: 0 | D28: 1 | E28: 2 | F28: 3 | G28: 4 | H28: 5 | I28: 6 | J28: 7 | K28: 8 | L28: 9
B29: 2016 | C29: 1110649 | D29: 1469662 | E29: 1538002 | F29: 1565073 | G29: 1576467 | H29: 1580496 | I29: 1585674 | J29: 1587403 | K29: 1589215 | L29: 1589933
B30: 2017 | C30: 1576262 | D30: 2205318 | E30: 2354787 | F30: 2230759 | G30: 2245257 | H30: 2253831 | I30: 2258279 | J30: 2262438 | K30: 2264178 | L30: 0
B31: 2018 | C31: 1742329 | D31: 2415874 | E31: 2377977 | F31: 2369185 | G31: 2389150 | H31: 2396455 | I31: 2399367 | J31: 2404449 | K31: 0 | L31: 0
B32: 2019 | C32: 1698356 | D32: 2292819 | E32: 2392891 | F32: 2425627 | G32: 2443236 | H32: 2453821 | I32: 2452899 | J32: 0 | K32: 0 | L32: 0
B33: 2020 | C33: 2110932 | D33: 2790835 | E33: 2881093 | F33: 2935977 | G33: 2960499 | H33: 2967414 | I33: 0 | J33: 0 | K33: 0 | L33: 0
B34: 2021 | C34: 2403311 | D34: 3331643 | E34: 3447605 | F34: 3478713 | G34: 3492079 | H34: 0 | I34: 0 | J34: 0 | K34: 0 | L34: 0
B35: 2022 | C35: 2619434 | D35: 3942297 | E35: 4144234 | F35: 4214025 | G35: 0 | H35: 0 | I35: 0 | J35: 0 | K35: 0 | L35: 0
B36: 2023 | C36: 3473828 | D36: 4737739 | E36: 4951063 | F36: 0 | G36: 0 | H36: 0 | I36: 0 | J36: 0 | K36: 0 | L36: 0
B37: 2024 | C37: 3490477 | D37: 4566277 | E37: 0 | F37: 0 | G37: 0 | H37: 0 | I37: 0 | J37: 0 | K37: 0 | L37: 0
B38: 2025 | C38: 3294181 | D38: 0 | E38: 0 | F38: 0 | G38: 0 | H38: 0 | I38: 0 | J38: 0 | K38: 0 | L38: 0
B44: Cumulative Net losses For PRIVATE PASSENGER AUTO LIABILITY/MEDICAL
B46: Years in which losses where incurred | C46: 0 | D46: 1 | E46: 2 | F46: 3 | G46: 4 | H46: 5 | I46: 6 | J46: 7 | K46: 8 | L46: 9
B47: 2016 | C47: 627300 | D47: 1197057 | E47: 1463910 | F47: 1613948 | G47: 1683851 | H47: 1714634 | I47: 1733819 | J47: 1739783 | K47: 1743177 | L47: 1744404
B48: 2017 | C48: 713613 | D48: 1353834 | E48: 1668308 | F48: 1828192 | G48: 1903816 | H48: 1949758 | I48: 1967667 | J48: 1972091 | K48: 1974588 | L48: 0
B49: 2018 | C49: 729709 | D49: 1393434 | E49: 1696364 | F49: 1857414 | G49: 1961385 | H49: 2005460 | I49: 2023705 | J49: 2032060 | K49: 0 | L49: 0
B50: 2019 | C50: 736718 | D50: 1413615 | E50: 1724888 | F50: 1926598 | G50: 2026405 | H50: 2073047 | I50: 2091823 | J50: 0 | K50: 0 | L50: 0
B51: 2020 | C51: 567550 | D51: 1091472 | E51: 1381767 | F51: 1532342 | G51: 1602589 | H51: 1635161 | I51: 0 | J51: 0 | K51: 0 | L51: 0
B52: 2021 | C52: 682680 | D52: 1479372 | E52: 1864207 | F52: 2058676 | G52: 2147312 | H52: 0 | I52: 0 | J52: 0 | K52: 0 | L52: 0
B53: 2022 | C53: 864009 | D53: 1844861 | E53: 2282246 | F53: 2492236 | G53: 0 | H53: 0 | I53: 0 | J53: 0 | K53: 0 | L53: 0
B54: 2023 | C54: 972555 | D54: 1996387 | E54: 2470313 | F54: 0 | G54: 0 | H54: 0 | I54: 0 | J54: 0 | K54: 0 | L54: 0
B55: 2024 | C55: 964949 | D55: 1914481 | E55: 0 | F55: 0 | G55: 0 | H55: 0 | I55: 0 | J55: 0 | K55: 0 | L55: 0
B56: 2025 | C56: 903083 | D56: 0 | E56: 0 | F56: 0 | G56: 0 | H56: 0 | I56: 0 | J56: 0 | K56: 0 | L56: 0
B62: Cumulative Net losses For COMMERCIAL AUTO/TRUCK LIABILITY/MEDICAL
B64: Years in which losses where incurred | C64: 0 | D64: 1 | E64: 2 | F64: 3 | G64: 4 | H64: 5 | I64: 6 | J64: 7 | K64: 8 | L64: 9
B65: 2016 | C65: 175900 | D65: 434523 | E65: 684975 | F65: 918187 | G65: 1027686 | H65: 1086054 | I65: 1139335 | J65: 1158109 | K65: 1163946 | L65: 1173340
B66: 2017 | C66: 191126 | D66: 467000 | E66: 755513 | F66: 960737 | G66: 1098501 | H66: 1188725 | I66: 1246138 | J66: 1268079 | K66: 1284463 | L66: 0
...

Sheet year to ultimate LDF
C8: Volume weighted loss development factor | E8: Year to ultimate loss development factor
C9: f1 | D9: =SUM('Loss Development'!D9:D17)/SUM('Loss Development'!C9:C17) -> 1.5609096 | E9: 1 to ultimate | F9: =PRODUCT(D9:D17) -> 2.3819593
C10: f2 | D10: =SUM('Loss Development'!E9:E16)/SUM('Loss Development'!D9:D16) -> 1.1686695 | E10: 2 to ultimate | F10: =PRODUCT(D10:D17) -> 1.5260072
C11: f3 | D11: =SUM('Loss Development'!F9:F15)/SUM('Loss Development'!E9:E15) -> 1.1041309 | E11: 3 to ultimate | F11: =PRODUCT(D11:D17) -> 1.3057645
C12: f4 | D12: =SUM('Loss Development'!G9:G14)/SUM('Loss Development'!F9:F14) -> 1.068879 | E12: 4 to ultimate | F12: =PRODUCT(D12:D17) -> 1.1826175
C13: f5 | D13: =SUM('Loss Development'!H9:H13)/SUM('Loss Development'!G9:G13) -> 1.0426806 | E13: 5 to ultimate | F13: =PRODUCT(D13:D17) -> 1.1064091
C14: f6 | D14: =SUM('Loss Development'!I9:I12)/SUM('Loss Development'!H9:H12) -> 1.0264347 | E14: 6 to ultimate | F14: =PRODUCT(D14:D17) -> 1.0611199
C15: f7 | D15: =SUM('Loss Development'!J9:J11)/SUM('Loss Development'!I9:I11) -> 1.0148569 | E15: 7 to ultimate | F15: =PRODUCT(D15:D17) -> 1.0337919
C16: f8 | D16: =SUM('Loss Development'!K9:K10)/SUM('Loss Development'!J9:J10) -> 1.0107069 | E16: 8 to ultimate | F16: =PRODUCT(D16:D17) -> 1.0186578
C17: f9 | D17: =SUM('Loss Development'!L9)/SUM('Loss Development'!K9) -> 1.0078666 | E17: 9 to ultimate | F17: =PRODUCT(D17) -> 1.0078666
C18: f10 | D18: 1 | E18: 10 to ultimate | F18: 1
C28: Volume weighted loss development factor | E28: Year to ultimate loss development factor
C29: f1 | D29: =SUM('Loss Development'!D29:D37)/SUM('Loss Development'!C29:C37) -> 1.3721469 | E29: 1 to ultimate | F29: =PRODUCT(D29:D37) -> 1.4524454
C30: f2 | D30: =SUM('Loss Development'!E29:E36)/SUM('Loss Development'!D29:D36) -> 1.0388794 | E30: 2 to ultimate | F30: =PRODUCT(D30:D37) -> 1.0585203
C31: f3 | D31: =SUM('Loss Development'!F29:F35)/SUM('Loss Development'!E29:E35) -> 1.0043252 | E31: 3 to ultimate | F31: =PRODUCT(D31:D37) -> 1.0189059
C32: f4 | D32: =SUM('Loss Development'!G29:G34)/SUM('Loss Development'!F29:F34) -> 1.0067545 | E32: 4 to ultimate | F32: =PRODUCT(D32:D37) -> 1.0145179
C33: f5 | D33: =SUM('Loss Development'!H29:H33)/SUM('Loss Development'!G29:G33) -> 1.0032208 | E33: 5 to ultimate | F33: =PRODUCT(D33:D37) -> 1.0077113
C34: f6 | D34: =SUM('Loss Development'!I29:I32)/SUM('Loss Development'!H29:H32) -> 1.0013375 | E34: 6 to ultimate | F34: =PRODUCT(D34:D37) -> 1.0044761
C35: f7 | D35: =SUM('Loss Development'!J29:J31)/SUM('Loss Development'!I29:I31) -> 1.0017571 | E35: 7 to ultimate | F35: =PRODUCT(D35:D37) -> 1.0031343
C36: f8 | D36: =SUM('Loss Development'!K29:K30)/SUM('Loss Development'!J29:J30) -> 1.0009226 | E36: 8 to ultimate | F36: =PRODUCT(D36:D37) -> 1.0013748
C37: f9 | D37: =SUM('Loss Development'!L29)/SUM('Loss Development'!K29) -> 1.0004518 | E37: 9 to ultimate | F37: =PRODUCT(D37) -> 1.0004518
C38: f10 | D38: 1 | E38: 10 to ultimate | F38: 1
C46: Volume weighted loss development factor | E46: Year to ultimate loss development factor
C47: f1 | D47: =SUM('Loss Development'!D47:D55)/SUM('Loss Development'!C47:C55) -> 1.9950937 | E47: 1 to ultimate | F47: =PRODUCT(D47:D55) -> 2.9511516
C48: f2 | D48: =SUM('Loss Development'!E47:E54)/SUM('Loss Development'!D47:D54) -> 1.2363605 | E48: 2 to ultimate | F48: =PRODUCT(D48:D55) -> 1.4792045
C49: f3 | D49: =SUM('Loss Development'!F47:F53)/SUM('Loss Development'!E47:E53) -> 1.1016179 | E49: 3 to ultimate | F49: =PRODUCT(D49:D55) -> 1.1964184
C50: f4 | D50: =SUM('Loss Development'!G47:G52)/SUM('Loss Development'!F47:F52) -> 1.0469798 | E50: 4 to ultimate | F50: =PRODUCT(D50:D55) -> 1.0860557
C51: f5 | D51: =SUM('Loss Development'!H47:H51)/SUM('Loss Development'!G47:G51) -> 1.0217927 | E51: 5 to ultimate | F51: =PRODUCT(D51:D55) -> 1.0373226
C52: f6 | D52: =SUM('Loss Development'!I47:I50)/SUM('Loss Development'!H47:H50) -> 1.009572 | E52: 6 to ultimate | F52: =PRODUCT(D52:D55) -> 1.0151987
C53: f7 | D53: =SUM('Loss Development'!J47:J49)/SUM('Loss Development'!I47:I49) -> 1.0032738 | E53: 7 to ultimate | F53: =PRODUCT(D53:D55) -> 1.0055734
C54: f8 | D54: =SUM('Loss Development'!K47:K48)/SUM('Loss Development'!J47:J48) -> 1.0015871 | E54: 8 to ultimate | F54: =PRODUCT(D54:D55) -> 1.0022921
C55: f9 | D55: =SUM('Loss Development'!L47)/SUM('Loss Development'!K47) -> 1.0007039 | E55: 9 to ultimate | F55: =PRODUCT(D55) -> 1.0007039
C56: f10 | D56: 1 | E56: 10 to ultimate | F56: 1
C64: Volume weighted loss development factor | E64: Year to ultimate loss development factor
C65: f1 | D65: =SUM('Loss Development'!D65:D73)/SUM('Loss Development'!C65:C73) -> 2.5890497 | E65: 1 to ultimate | F65: =PRODUCT(D65:D73) -> 7.4946462
C66: f2 | D66: =SUM('Loss Development'!E65:E72)/SUM('Loss Development'!D65:D72) -> 1.6327859 | E66: 2 to ultimate | F66: =PRODUCT(D66:D73) -> 2.8947479
C67: f3 | D67: =SUM('Loss Development'!F65:F71)/SUM('Loss Development'!E65:E71) -> 1.3194015 | E67: 3 to ultimate | F67: =PRODUCT(D67:D73) -> 1.7728888
C68: f4 | D68: =SUM('Loss Development'!G65:G70)/SUM('Loss Development'!F65:F70) -> 1.1612716 | E68: 4 to ultimate | F68: =PRODUCT(D68:D73) -> 1.3437069
C69: f5 | D69: =SUM('Loss Development'!H65:H69)/SUM('Loss Development'!G65:G69) -> 1.0732278 | E69: 5 to ultimate | F69: =PRODUCT(D69:D73) -> 1.1570996
C70: f6 | D70: =SUM('Loss Development'!I65:I68)/SUM('Loss Development'!H65:H68) -> 1.0410057 | E70: 6 to ultimate | F70: =PRODUCT(D70:D73) -> 1.0781491
...

Sheet loss reserve and loss ratio
C8: Accident Year | D8: Cumulative paid loss to date | E8: Age at latest evaluation | F8: Ultimate Loss development Factor | G8: Expected Loss(Chain Ladder Method) | H8: Loss Reserves(Chain Ladder Method) | I8: Earned Premiums | J8: Expected Loss Ratio
C9: 2016 | D9: ='Loss Development'!L9 -> 11798741 | E9: 9 | F9: ='year to ultimate LDF'!F18 -> 1 | G9: =PRODUCT(D9,F9) -> 11798741 | H9: =G9-D9 -> 0 | I9: 22928545 | J9: =(G9/I9)*100 -> 51.458743
C10: 2017 | D10: ='Loss Development'!K10 -> 13870301 | E10: 8 | F10: ='year to ultimate LDF'!F17 -> 1.0078666 | G10: =PRODUCT(D10,F10) -> 13979414 | H10: =G10-D10 -> 109112.67 | I10: 23974677 | J10: =(G10/I10)*100 -> 58.30908
C11: 2018 | D11: ='Loss Development'!J11 -> 14589305 | E11: 7 | F11: ='year to ultimate LDF'!F16 -> 1.0186578 | G11: =PRODUCT(D11,F11) -> 14861509 | H11: =G11-D11 -> 272203.97 | I11: 25218935 | J11: =(G11/I11)*100 -> 58.929963
C12: 2019 | D12: ='Loss Development'!I12 -> 14995725 | E12: 6 | F12: ='year to ultimate LDF'!F15 -> 1.0337919 | G12: =PRODUCT(D12,F12) -> 15502459 | H12: =G12-D12 -> 506734.21 | I12: 26381533 | J12: =(G12/I12)*100 -> 58.762541
C13: 2020 | D13: ='Loss Development'!H13 -> 13452890 | E13: 5 | F13: ='year to ultimate LDF'!F14 -> 1.0611199 | G13: =PRODUCT(D13,F13) -> 14275129 | H13: =G13-D13 -> 822238.93 | I13: 27135373 | J13: =(G13/I13)*100 -> 52.607086
C14: 2021 | D14: ='Loss Development'!G14 -> 15019191 | E14: 4 | F14: ='year to ultimate LDF'!F13 -> 1.1064091 | G14: =PRODUCT(D14,F14) -> 16617370 | H14: =G14-D14 -> 1598179.3 | I14: 28782907 | J14: =(G14/I14)*100 -> 57.733468
C15: 2022 | D15: ='Loss Development'!F15 -> 16753459 | E15: 3 | F15: ='year to ultimate LDF'!F12 -> 1.1826175 | G15: =PRODUCT(D15,F15) -> 19812933 | H15: =G15-D15 -> 3059474.1 | I15: 31715601 | J15: =(G15/I15)*100 -> 62.470622
C16: 2023 | D16: ='Loss Development'!E16 -> 16790693 | E16: 2 | F16: ='year to ultimate LDF'!F11 -> 1.3057645 | G16: =PRODUCT(D16,F16) -> 21924690 | H16: =G16-D16 -> 5133997.5 | I16: 35642519 | J16: =(G16/I16)*100 -> 61.512741
C17: 2024 | D17: ='Loss Development'!D17 -> 14226152 | E17: 1 | F17: ='year to ultimate LDF'!F10 -> 1.5260072 | G17: =PRODUCT(D17,F17) -> 21709210 | H17: =G17-D17 -> 7483057.9 | I17: 39672438 | J17: =(G17/I17)*100 -> 54.721139
C18: 2025 | D18: ='Loss Development'!C18 -> 8975277 | E18: 0 | F18: ='year to ultimate LDF'!F9 -> 2.3819593 | G18: =PRODUCT(D18,F18) -> 21378745 | H18: =G18-D18 -> 12403468 | I18: 41616772 | J18: =(G18/I18)*100 -> 51.370502
F19: Total | G19: =SUM(G9:G18) -> 1.718602e+08 | H19: =SUM(H9:H18) -> 31388466 | I19: =SUM(I9:I18) -> 303069300 | J19: =(G19/I19)*100 -> 56.706568
C28: Accident Year | D28: Cumulative paid loss to date | E28: Age at latest evaluation | F28: Ultimate Loss development Factor | G28: Expected Loss(Chain Ladder Method) | H28: Loss Reserves(Chain Ladder Method) | I28: Earned Premiums | J28: Expected Loss Ratio
C29: 2016 | D29: ='Loss Development'!L29 -> 1589933 | E29: 9 | F29: ='year to ultimate LDF'!F38 -> 1 | G29: =PRODUCT(D29,F29) -> 1589933 | H29: =G29-D29 -> 0 | I29: 3448337 | J29: =(G29/I29)*100 -> 46.10724
C30: 2017 | D30: ='Loss Development'!K30 -> 2264178 | E30: 8 | F30: ='year to ultimate LDF'!F37 -> 1.0004518 | G30: =PRODUCT(D30,F30) -> 2265200.9 | H30: =G30-D30 -> 1022.9452 | I30: 3587453 | J30: =(G30/I30)*100 -> 63.142317
C31: 2018 | D31: ='Loss Development'!J31 -> 2404449 | E31: 7 | F31: ='year to ultimate LDF'!F36 -> 1.0013748 | G31: =PRODUCT(D31,F31) -> 2407754.8 | H31: =G31-D31 -> 3305.7513 | I31: 3783189 | J31: =(G31/I31)*100 -> 63.643523
C32: 2019 | D32: ='Loss Development'!I32 -> 2452899 | E32: 6 | F32: ='year to ultimate LDF'!F35 -> 1.0031343 | G32: =PRODUCT(D32,F32) -> 2460587.2 | H32: =G32-D32 -> 7688.2229 | I32: 4039546 | J32: =(G32/I32)*100 -> 60.912469
C33: 2020 | D33: ='Loss Development'!H33 -> 2967414 | E33: 5 | F33: ='year to ultimate LDF'!F34 -> 1.0044761 | G33: =PRODUCT(D33,F33) -> 2980696.4 | H33: =G33-D33 -> 13282.362 | I33: 4628946 | J33: =(G33/I33)*100 -> 64.39255
C34: 2021 | D34: ='Loss Development'!G34 -> 3492079 | E34: 4 | F34: ='year to ultimate LDF'!F33 -> 1.0077113 | G34: =PRODUCT(D34,F34) -> 3519007.3 | H34: =G34-D34 -> 26928.333 | I34: 5246837 | J34: =(G34/I34)*100 -> 67.069119
C35: 2022 | D35: ='Loss Development'!F35 -> 4214025 | E35: 3 | F35: ='year to ultimate LDF'!F32 -> 1.0145179 | G35: =PRODUCT(D35,F35) -> 4275203.7 | H35: =G35-D35 -> 61178.703 | I35: 6076011 | J35: =(G35/I35)*100 -> 70.362014
C36: 2023 | D36: ='Loss Development'!E36 -> 4951063 | E36: 2 | F36: ='year to ultimate LDF'!F31 -> 1.0189059 | G36: =PRODUCT(D36,F36) -> 5044667.3 | H36: =G36-D36 -> 93604.271 | I36: 7048878 | J36: =(G36/I36)*100 -> 71.566954
C37: 2024 | D37: ='Loss Development'!D37 -> 4566277 | E37: 1 | F37: ='year to ultimate LDF'!F30 -> 1.0585203 | G37: =PRODUCT(D37,F37) -> 4833497.1 | H37: =G37-D37 -> 267220.09 | I37: 7844982 | J37: =(G37/I37)*100 -> 61.612596
C38: 2025 | D38: ='Loss Development'!C38 -> 3294181 | E38: 0 | F38: ='year to ultimate LDF'!F29 -> 1.4524454 | G38: =PRODUCT(D38,F38) -> 4784618 | H38: =G38-D38 -> 1490437 | I38: 8423313 | J38: =(G38/I38)*100 -> 56.802092
F39: Total | G39: =SUM(G29:G38) -> 34161166 | H39: =SUM(H29:H38) -> 1964667.7 | I39: =SUM(I29:I38) -> 54127492 | J39: =(G39/I39)*100 -> 63.112412
C46: Accident Year | D46: Cumulative paid loss to date | E46: Age at latest evaluation | F46: Ultimate Loss development Factor | G46: Expected Loss(Chain Ladder Method) | H46: Loss Reserves(Chain Ladder Method) | I46: Earned Premiums | J46: Expected Loss Ratio
C47: 2016 | D47: ='Loss Development'!L47 -> 1744404 | E47: 9 | F47: ='year to ultimate LDF'!F56 -> 1 | G47: =PRODUCT(D47,F47) -> 1744404 | H47: =G47-D47 -> 0 | I47: 2453792 | J47: =(G47/I47)*100 -> 71.090133
C48: 2017 | D48: ='Loss Development'!K48 -> 1974588 | E48: 8 | F48: ='year to ultimate LDF'!F55 -> 1.0007039 | G48: =PRODUCT(D48,F48) -> 1975977.9 | H48: =G48-D48 -> 1389.8872 | I48: 2834323 | J48: =(G48/I48)*100 -> 69.716045
C49: 2018 | D49: ='Loss Development'!J49 -> 2032060 | E49: 7 | F49: ='year to ultimate LDF'!F54 -> 1.0022921 | G49: =PRODUCT(D49,F49) -> 2036717.6 | H49: =G49-D49 -> 4657.6304 | I49: 3119812 | J49: =(G49/I49)*100 -> 65.283345
C50: 2019 | D50: ='Loss Development'!I50 -> 2091823 | E50: 6 | F50: ='year to ultimate LDF'!F53 -> 1.0055734 | G50: =PRODUCT(D50,F50) -> 2103481.5 | H50: =G50-D50 -> 11658.471 | I50: 3249753 | J50: =(G50/I50)*100 -> 64.727426
C51: 2020 | D51: ='Loss Development'!H51 -> 1635161 | E51: 5 | F51: ='year to ultimate LDF'!F52 -> 1.0151987 | G51: =PRODUCT(D51,F51) -> 1660013.3 | H51: =G51-D51 -> 24852.319 | I51: 3204232 | J51: =(G51/I51)*100 -> 51.806902
C52: 2021 | D52: ='Loss Development'!G52 -> 2147312 | E52: 4 | F52: ='year to ultimate LDF'!F51 -> 1.0373226 | G52: =PRODUCT(D52,F52) -> 2227455.2 | H52: =G52-D52 -> 80143.213 | I52: 3410569 | J52: =(G52/I52)*100 -> 65.310369
C53: 2022 | D53: ='Loss Development'!F53 -> 2492236 | E53: 3 | F53: ='year to ultimate LDF'!F50 -> 1.0860557 | G53: =PRODUCT(D53,F53) -> 2706707.2 | H53: =G53-D53 -> 214471.2 | I53: 3676366 | J53: =(G53/I53)*100 -> 73.62453
C54: 2023 | D54: ='Loss Development'!E54 -> 2470313 | E54: 2 | F54: ='year to ultimate LDF'!F49 -> 1.1964184 | G54: =PRODUCT(D54,F54) -> 2955528 | H54: =G54-D54 -> 485215.03 | I54: 4072128 | J54: =(G54/I54)*100 -> 72.579448
C55: 2024 | D55: ='Loss Development'!D55 -> 1914481 | E55: 1 | F55: ='year to ultimate LDF'!F48 -> 1.4792045 | G55: =PRODUCT(D55,F55) -> 2831909 | H55: =G55-D55 -> 917427.98 | I55: 4479690 | J55: =(G55/I55)*100 -> 63.216628
C56: 2025 | D56: ='Loss Development'!C56 -> 903083 | E56: 0 | F56: ='year to ultimate LDF'!F47 -> 2.9511516 | G56: =PRODUCT(D56,F56) -> 2665134.8 | H56: =G56-D56 -> 1762051.8 | I56: 4542002 | J56: =(G56/I56)*100 -> 58.677535
F57: Total | G57: =SUM(G47:G56) -> 22907329 | H57: =SUM(H47:H56) -> 3501867.6 | I57: =SUM(I47:I56) -> 35042667 | J57: =(G57/I57)*100 -> 65.369821
C64: Accident Year | D64: Cumulative paid loss to date | E64: Age at latest evaluation | F64: Ultimate Loss development Factor | G64: Expected Loss(Chain Ladder Method) | H64: Loss Reserves(Chain Ladder Method) | I64: Earned Premiums | J64: Expected Loss Ratio
C65: 2016 | D65: ='Loss Development'!L65 -> 1173340 | E65: 9 | F65: ='year to ultimate LDF'!F74 -> 1 | G65: =PRODUCT(D65,F65) -> 1173340 | H65: =G65-D65 -> 0 | I65: 1584689 | J65: =(G65/I65)*100 -> 74.042288
C66: 2017 | D66: ='Loss Development'!K66 -> 1284463 | E66: 8 | F66: ='year to ultimate LDF'!F73 -> 1.0080708 | G66: =PRODUCT(D66,F66) -> 1294829.7 | H66: =G66-D66 -> 10366.671 | I66: 1684946 | J66: =(G66/I66)*100 -> 76.846954
C67: 2018 | D67: ='Loss Development'!J67 -> 1470916 | E67: 7 | F67: ='year to ultimate LDF'!F72 -> 1.0173036 | G67: =PRODUCT(D67,F67) -> 1496368.1 | H67: =G67-D67 -> 25452.072 | I67: 1886777 | J67: =(G67/I67)*100 -> 79.308157
...

Sheet rate adequacy verdict
B8: Accident Year | C8: Earned Premiums | D8: Indicative Loss Ratio(Percentage) | E8: Target Loss Ratio%(Average ) | F8: Difference(Points) | G8: Rate Adequacy Verdict
B9: 2016 | C9: ='loss reserve and loss ratio'!I9 -> 22928545 | D9: ='loss reserve and loss ratio'!J9 -> 51.458743 | E9: ='loss reserve and loss ratio'!J19 -> 56.706568 | F9: =D9-E9 -> -5.2478256 | G9: Overcharged
B10: 2017 | C10: ='loss reserve and loss ratio'!I10 -> 23974677 | D10: ='loss reserve and loss ratio'!J10 -> 58.30908 | E10: 56.706568 | F10: =D10-E10 -> 1.6025119 | G10: Roughly Adequate
B11: 2018 | C11: ='loss reserve and loss ratio'!I11 -> 25218935 | D11: ='loss reserve and loss ratio'!J11 -> 58.929963 | E11: 56.706568 | F11: =D11-E11 -> 2.2233942 | G11: Roughly Adequate
B12: 2019 | C12: ='loss reserve and loss ratio'!I12 -> 26381533 | D12: ='loss reserve and loss ratio'!J12 -> 58.762541 | E12: 56.706568 | F12: =D12-E12 -> 2.0559728 | G12: Roughly Adequate
B13: 2020 | C13: ='loss reserve and loss ratio'!I13 -> 27135373 | D13: ='loss reserve and loss ratio'!J13 -> 52.607086 | E13: 56.706568 | F13: =D13-E13 -> -4.0994828 | G13: Roughly Adequate
B14: 2021 | C14: ='loss reserve and loss ratio'!I14 -> 28782907 | D14: ='loss reserve and loss ratio'!J14 -> 57.733468 | E14: 56.706568 | F14: =D14-E14 -> 1.0268991 | G14: Roughly Adequate
B15: 2022 | C15: ='loss reserve and loss ratio'!I15 -> 31715601 | D15: ='loss reserve and loss ratio'!J15 -> 62.470622 | E15: 56.706568 | F15: =D15-E15 -> 5.7640533 | G15: Undercharged
B16: 2023 | C16: ='loss reserve and loss ratio'!I16 -> 35642519 | D16: ='loss reserve and loss ratio'!J16 -> 61.512741 | E16: 56.706568 | F16: =D16-E16 -> 4.8061728 | G16: Roughly Adequate
B17: 2024 | C17: ='loss reserve and loss ratio'!I17 -> 39672438 | D17: ='loss reserve and loss ratio'!J17 -> 54.721139 | E17: 56.706568 | F17: =D17-E17 -> -1.9854297 | G17: Roughly Adequate
B18: 2025 | C18: ='loss reserve and loss ratio'!I18 -> 41616772 | D18: ='loss reserve and loss ratio'!J18 -> 51.370502 | E18: 56.706568 | F18: =D18-E18 -> -5.3360668 | G18: Overcharged
B28: Accident Year | C28: Earned Premiums | D28: Indicative Loss Ratio(Percentage) | E28: Target Loss Ratio%(Average ) | F28: Difference(Points) | G28: Rate Adequacy Verdict
B29: 2016 | C29: ='loss reserve and loss ratio'!I29 -> 3448337 | D29: ='loss reserve and loss ratio'!J29 -> 46.10724 | E29: 63.11 | F29: =D29-E29 -> -17.00276 | G29: Overcharged
B30: 2017 | C30: ='loss reserve and loss ratio'!I30 -> 3587453 | D30: ='loss reserve and loss ratio'!J30 -> 63.142317 | E30: 63.11 | F30: =D30-E30 -> 0.032316991 | G30: Roughly Adequate
B31: 2018 | C31: ='loss reserve and loss ratio'!I31 -> 3783189 | D31: ='loss reserve and loss ratio'!J31 -> 63.643523 | E31: 63.11 | F31: =D31-E31 -> 0.53352273 | G31: Roughly Adequate
B32: 2019 | C32: ='loss reserve and loss ratio'!I32 -> 4039546 | D32: ='loss reserve and loss ratio'!J32 -> 60.912469 | E32: 63.11 | F32: =D32-E32 -> -2.1975306 | G32: Roughly Adequate
B33: 2020 | C33: ='loss reserve and loss ratio'!I33 -> 4628946 | D33: ='loss reserve and loss ratio'!J33 -> 64.39255 | E33: 63.11 | F33: =D33-E33 -> 1.2825499 | G33: Roughly Adequate
B34: 2021 | C34: ='loss reserve and loss ratio'!I34 -> 5246837 | D34: ='loss reserve and loss ratio'!J34 -> 67.069119 | E34: 63.11 | F34: =D34-E34 -> 3.9591186 | G34: Roughly Adequate
B35: 2022 | C35: ='loss reserve and loss ratio'!I35 -> 6076011 | D35: ='loss reserve and loss ratio'!J35 -> 70.362014 | E35: 63.11 | F35: =D35-E35 -> 7.2520139 | G35: Undercharged
B36: 2023 | C36: ='loss reserve and loss ratio'!I36 -> 7048878 | D36: ='loss reserve and loss ratio'!J36 -> 71.566954 | E36: 63.11 | F36: =D36-E36 -> 8.4569539 | G36: Undercharged
B37: 2024 | C37: ='loss reserve and loss ratio'!I37 -> 7844982 | D37: ='loss reserve and loss ratio'!J37 -> 61.612596 | E37: 63.11 | F37: =D37-E37 -> -1.4974037 | G37: Roughly Adequate
B38: 2025 | C38: ='loss reserve and loss ratio'!I38 -> 8423313 | D38: ='loss reserve and loss ratio'!J38 -> 56.802092 | E38: 63.11 | F38: =D38-E38 -> -6.3079076 | G38: Overcharged
B46: Accident Year | C46: Earned Premiums | D46: Indicative Loss Ratio(Percentage) | E46: Target Loss Ratio%(Average ) | F46: Difference(Points) | G46: Rate Adequacy Verdict
B47: 2016 | C47: ='loss reserve and loss ratio'!I47 -> 2453792 | D47: ='loss reserve and loss ratio'!J47 -> 71.090133 | E47: 65.37 | F47: =D47-E47 -> 5.7201331 | G47: Undercharged
B48: 2017 | C48: ='loss reserve and loss ratio'!I48 -> 2834323 | D48: ='loss reserve and loss ratio'!J48 -> 69.716045 | E48: 65.37 | F48: =D48-E48 -> 4.3460446 | G48: Roughly Adequate
B49: 2018 | C49: ='loss reserve and loss ratio'!I49 -> 3119812 | D49: ='loss reserve and loss ratio'!J49 -> 65.283345 | E49: 65.37 | F49: =D49-E49 -> -0.086655028 | G49: Roughly Adequate
B50: 2019 | C50: ='loss reserve and loss ratio'!I50 -> 3249753 | D50: ='loss reserve and loss ratio'!J50 -> 64.727426 | E50: 65.37 | F50: =D50-E50 -> -0.64257393 | G50: Roughly Adequate
B51: 2020 | C51: ='loss reserve and loss ratio'!I51 -> 3204232 | D51: ='loss reserve and loss ratio'!J51 -> 51.806902 | E51: 65.37 | F51: =D51-E51 -> -13.563098 | G51: Overcharged
B52: 2021 | C52: ='loss reserve and loss ratio'!I52 -> 3410569 | D52: ='loss reserve and loss ratio'!J52 -> 65.310369 | E52: 65.37 | F52: =D52-E52 -> -0.0596306 | G52: Roughly Adequate
B53: 2022 | C53: ='loss reserve and loss ratio'!I53 -> 3676366 | D53: ='loss reserve and loss ratio'!J53 -> 73.62453 | E53: 65.37 | F53: =D53-E53 -> 8.2545304 | G53: Undercharged
B54: 2023 | C54: ='loss reserve and loss ratio'!I54 -> 4072128 | D54: ='loss reserve and loss ratio'!J54 -> 72.579448 | E54: 65.37 | F54: =D54-E54 -> 7.2094481 | G54: Undercharged
B55: 2024 | C55: ='loss reserve and loss ratio'!I55 -> 4479690 | D55: ='loss reserve and loss ratio'!J55 -> 63.216628 | E55: 65.37 | F55: =D55-E55 -> -2.1533715 | G55: Roughly Adequate
B56: 2025 | C56: ='loss reserve and loss ratio'!I56 -> 4542002 | D56: ='loss reserve and loss ratio'!J56 -> 58.677535 | E56: 65.37 | F56: =D56-E56 -> -6.6924645 | G56: Overcharged
B64: Accident Year | C64: Earned Premiums | D64: Indicative Loss Ratio(Percentage) | E64: Target Loss Ratio%(Average ) | F64: Difference(Points) | G64: Rate Adequacy Verdict
B65: 2016 | C65: ='loss reserve and loss ratio'!I65 -> 1584689 | D65: ='loss reserve and loss ratio'!J65 -> 74.042288 | E65: 67.6 | F65: =D65-E65 -> 6.4422884 | G65: Undercharged
B66: 2017 | C66: ='loss reserve and loss ratio'!I66 -> 1684946 | D66: ='loss reserve and loss ratio'!J66 -> 76.846954 | E66: 67.6 | F66: =D66-E66 -> 9.2469536 | G66: Undercharged
B67: 2018 | C67: ='loss reserve and loss ratio'!I67 -> 1886777 | D67: ='loss reserve and loss ratio'!J67 -> 79.308157 | E67: 67.6 | F67: =D67-E67 -> 11.708157 | G67: Undercharged
B68: 2019 | C68: ='loss reserve and loss ratio'!I68 -> 2066132 | D68: ='loss reserve and loss ratio'!J68 -> 82.792692 | E68: 67.6 | F68: =D68-E68 -> 15.192692 | G68: Undercharged
B69: 2020 | C69: ='loss reserve and loss ratio'!I69 -> 2156573 | D69: ='loss reserve and loss ratio'!J69 -> 58.001059 | E69: 67.6 | F69: =D69-E69 -> -9.5989411 | G69: Overcharged
B70: 2021 | C70: ='loss reserve and loss ratio'!I70 -> 2244548 | D70: ='loss reserve and loss ratio'!J70 -> 66.938364 | E70: 67.6 | F70: =D70-E70 -> -0.66163561 | G70: Roughly Adequate
...
