Workbook

Sheet loss development
B6: Combined Cumulative Net Losses Across All Business
B8: Years in which losses where incurred | C8: 0 | D8: 1 | E8: 2 | F8: 3 | G8: 4 | H8: 5 | I8: 6 | J8: 7 | K8: 8 | L8: 9
B9: 2016 | C9: 614934 | D9: 1382959 | E9: 1778178 | F9: 2117452 | G9: 2302752 | H9: 2433140 | I9: 2554231 | J9: 2642848 | K9: 2715254 | L9: 2761135
B10: 2017 | C10: 981175 | D10: 1730257 | E10: 2112888 | F10: 2401046 | G10: 2601193 | H10: 2795207 | I10: 2961170 | J10: 3063588 | K10: 3153791 | L10: 0
B11: 2018 | C11: 985541 | D11: 1840750 | E11: 2228910 | F11: 2490315 | G11: 2759183 | H11: 2937599 | I11: 3109592 | J11: 3195426 | K11: 0 | L11: 0
B12: 2019 | C12: 1201241 | D12: 1815635 | E12: 2111383 | F12: 2419389 | G12: 2638912 | H12: 2786081 | I12: 2881238 | J12: 0 | K12: 0 | L12: 0
B13: 2020 | C13: 1148786 | D13: 1735749 | E13: 1998947 | F13: 2219411 | G13: 2422855 | H13: 2555281 | I13: 0 | J13: 0 | K13: 0 | L13: 0
B14: 2021 | C14: 1223228 | D14: 2028937 | E14: 2306989 | F14: 2573309 | G14: 2780307 | H14: 0 | I14: 0 | J14: 0 | K14: 0 | L14: 0
B15: 2022 | C15: 1482407 | D15: 2384101 | E15: 2768547 | F15: 3028044 | G15: 0 | H15: 0 | I15: 0 | J15: 0 | K15: 0 | L15: 0
B16: 2023 | C16: 1543016 | D16: 2329972 | E16: 2690711 | F16: 0 | G16: 0 | H16: 0 | I16: 0 | J16: 0 | K16: 0 | L16: 0
B17: 2024 | C17: 1213230 | D17: 2216863 | E17: 0 | F17: 0 | G17: 0 | H17: 0 | I17: 0 | J17: 0 | K17: 0 | L17: 0
B18: 2025 | C18: 1045692 | D18: 0 | E18: 0 | F18: 0 | G18: 0 | H18: 0 | I18: 0 | J18: 0 | K18: 0 | L18: 0
B26: Cumulative Net losses For Homeowners and Farmowners
B28: Years in which losses where incurred | C28: 0 | D28: 1 | E28: 2 | F28: 3 | G28: 4 | H28: 5 | I28: 6 | J28: 7 | K28: 8 | L28: 9
B29: 2016 | C29: 373 | D29: 1135 | E29: 1327 | F29: 1359 | G29: 1515 | H29: 1524 | I29: 1539 | J29: 1539 | K29: 1540 | L29: 1540
B30: 2017 | C30: 205 | D30: 834 | E30: 1000 | F30: 1039 | G30: 1052 | H30: 1199 | I30: 1205 | J30: 1210 | K30: 1210 | L30: 0
B31: 2018 | C31: 680 | D31: 1329 | E31: 1471 | F31: 1506 | G31: 1514 | H31: 1525 | I31: 1529 | J31: 1527 | K31: 0 | L31: 0
B32: 2019 | C32: 2736 | D32: 5323 | E32: 5895 | F32: 6045 | G32: 6185 | H32: 6195 | I32: 6196 | J32: 0 | K32: 0 | L32: 0
B33: 2020 | C33: 8434 | D33: 14773 | E33: 16203 | F33: 16595 | G33: 16632 | H33: 16666 | I33: 0 | J33: 0 | K33: 0 | L33: 0
B34: 2021 | C34: 24006 | D34: 42654 | E34: 44895 | F34: 45396 | G34: 45701 | H34: 0 | I34: 0 | J34: 0 | K34: 0 | L34: 0
B35: 2022 | C35: 21056 | D35: 36507 | E35: 38464 | F35: 38726 | G35: 0 | H35: 0 | I35: 0 | J35: 0 | K35: 0 | L35: 0
B36: 2023 | C36: 24837 | D36: 36561 | E36: 37785 | F36: 0 | G36: 0 | H36: 0 | I36: 0 | J36: 0 | K36: 0 | L36: 0
B37: 2024 | C37: 16732 | D37: 23980 | E37: 0 | F37: 0 | G37: 0 | H37: 0 | I37: 0 | J37: 0 | K37: 0 | L37: 0
B38: 2025 | C38: 24301 | D38: 0 | E38: 0 | F38: 0 | G38: 0 | H38: 0 | I38: 0 | J38: 0 | K38: 0 | L38: 0
B44: Cumulative Net losses For PRIVATE PASSENGER AUTO LIABILITY/MEDICAL
B46: Years in which losses where incurred | C46: 0 | D46: 1 | E46: 2 | F46: 3 | G46: 4 | H46: 5 | I46: 6 | J46: 7 | K46: 8 | L46: 9
B47: 2016
B48: 2017
B49: 2018
B50: 2019
B51: 2020 | E51: Insufficient Info
B52: 2021
B53: 2022
B54: 2023
B55: 2024
B56: 2025
B62: Cumulative Net losses For COMMERCIAL AUTO/TRUCK LIABILITY/MEDICAL
B64: Years in which losses where incurred | C64: 0 | D64: 1 | E64: 2 | F64: 3 | G64: 4 | H64: 5 | I64: 6 | J64: 7 | K64: 8 | L64: 9
B65: 2016 | C65: 33814 | D65: 95496 | E65: 157208 | F65: 224071 | G65: 256326 | H65: 270358 | I65: 284227 | J65: 292383 | K65: 297471 | L65: 303406
B66: 2017 | C66: 33429 | D66: 90151 | E66: 153804 | F66: 206816 | G66: 243630 | H66: 268973 | I66: 280458 | J66: 287024 | K66: 288681 | L66: 0
...

Sheet year to ultimate LDF
C8: Volume weighted loss development factor | E8: Year to ultimate loss development factor
C9: f1 | D9: =SUM('loss development'!D9:D17)/SUM('loss development'!C9:C17) -> 1.6803892 | E9: 1 to ultimate | F9: =PRODUCT(D9:D17) -> 2.9335031
C10: f2 | D10: =SUM('loss development'!E9:E16)/SUM('loss development'!D9:D16) -> 1.1802288 | E10: 2 to ultimate | F10: =PRODUCT(D10:D17) -> 1.7457283
C11: f3 | D11: =SUM('loss development'!F9:F15)/SUM('loss development'!E9:E15) -> 1.1269531 | E11: 3 to ultimate | F11: =PRODUCT(D11:D17) -> 1.479144
C12: f4 | D12: =SUM('loss development'!G9:G14)/SUM('loss development'!F9:F14) -> 1.0903092 | E12: 4 to ultimate | F12: =PRODUCT(D12:D17) -> 1.3125161
C13: f5 | D13: =SUM('loss development'!H9:H13)/SUM('loss development'!G9:G13) -> 1.0614868 | E13: 5 to ultimate | F13: =PRODUCT(D13:D17) -> 1.2038017
C14: f6 | D14: =SUM('loss development'!I9:I12)/SUM('loss development'!H9:H12) -> 1.0506029 | E14: 6 to ultimate | F14: =PRODUCT(D14:D17) -> 1.1340713
C15: f7 | D15: =SUM('loss development'!J9:J11)/SUM('loss development'!I9:I11) -> 1.0321008 | E15: 7 to ultimate | F15: =PRODUCT(D15:D17) -> 1.0794481
C16: f8 | D16: =SUM('loss development'!K9:K10)/SUM('loss development'!J9:J10) -> 1.0284957 | E16: 8 to ultimate | F16: =PRODUCT(D16:D17) -> 1.0458747
C17: f9 | D17: =SUM('loss development'!L9)/SUM('loss development'!K9) -> 1.0168975 | E17: 9 to ultimate | F17: =PRODUCT(D17) -> 1.0168975
C18: f10 | D18: 1 | E18: 10 to ultimate | F18: 1
C28: Volume weighted loss development factor | E28: Year to ultimate loss development factor
C29: f1 | D29: =SUM('loss development'!D29:D37)/SUM('loss development'!C29:C37) -> 1.6464531 | E29: 1 to ultimate | F29: =PRODUCT(D29:D37) -> 1.7991902
C30: f2 | D30: =SUM('loss development'!E29:E36)/SUM('loss development'!D29:D36) -> 1.0569597 | E30: 2 to ultimate | F30: =PRODUCT(D30:D37) -> 1.0927673
C31: f3 | D31: =SUM('loss development'!F29:F35)/SUM('loss development'!E29:E35) -> 1.0129147 | E31: 3 to ultimate | F31: =PRODUCT(D31:D37) -> 1.033878
C32: f4 | D32: =SUM('loss development'!G29:G34)/SUM('loss development'!F29:F34) -> 1.0091604 | E32: 4 to ultimate | F32: =PRODUCT(D32:D37) -> 1.020696
C33: f5 | D33: =SUM('loss development'!H29:H33)/SUM('loss development'!G29:G33) -> 1.0078444 | E33: 5 to ultimate | F33: =PRODUCT(D33:D37) -> 1.0114308
C34: f6 | D34: =SUM('loss development'!I29:I32)/SUM('loss development'!H29:H32) -> 1.0024897 | E34: 6 to ultimate | F34: =PRODUCT(D34:D37) -> 1.0035585
C35: f7 | D35: =SUM('loss development'!J29:J31)/SUM('loss development'!I29:I31) -> 1.0007021 | E35: 7 to ultimate | F35: =PRODUCT(D35:D37) -> 1.0010661
C36: f8 | D36: =SUM('loss development'!K29:K30)/SUM('loss development'!J29:J30) -> 1.0003638 | E36: 8 to ultimate | F36: =PRODUCT(D36:D37) -> 1.0003638
C37: f9 | D37: =SUM('loss development'!L29)/SUM('loss development'!K29) -> 1 | E37: 9 to ultimate | F37: =PRODUCT(D37) -> 1
C38: f10 | D38: 1 | E38: 10 to ultimate | F38: 1
C46: Volume weighted loss development factor | E46: Year to ultimate loss development factor
C47: f1
C48: f2 | E48: Insufficient Info
C49: f3
C50: f4
C51: f5
C52: f6
C53: f7
C54: f8
C55: f9
C56: f10
C64: Volume weighted loss development factor | E64: Year to ultimate loss development factor
C65: f1 | D65: =SUM('loss development'!D65:D73)/SUM('loss development'!C65:C73) -> 3.2526497 | E65: 1 to ultimate | F65: =PRODUCT(D65:D73) -> 12.533637
C66: f2 | D66: =SUM('loss development'!E65:E72)/SUM('loss development'!D65:D72) -> 1.8200008 | E66: 2 to ultimate | F66: =PRODUCT(D66:D73) -> 3.853362
C67: f3 | D67: =SUM('loss development'!F65:F71)/SUM('loss development'!E65:E71) -> 1.4261496 | E67: 3 to ultimate | F67: =PRODUCT(D67:D73) -> 2.117231
C68: f4 | D68: =SUM('loss development'!G65:G70)/SUM('loss development'!F65:F70) -> 1.2166059 | E68: 4 to ultimate | F68: =PRODUCT(D68:D73) -> 1.4845784
C69: f5 | D69: =SUM('loss development'!H65:H69)/SUM('loss development'!G65:G69) -> 1.0935076 | E69: 5 to ultimate | F69: =PRODUCT(D69:D73) -> 1.2202624
C70: f6 | D70: =SUM('loss development'!I65:I68)/SUM('loss development'!H65:H68) -> 1.0568416 | E70: 6 to ultimate | F70: =PRODUCT(D70:D73) -> 1.1159158
...

Sheet loss reserve and loss ratio
C8: Accident Year | D8: Cumulative paid loss to date | E8: Age at latest evaluation | F8: Ultimate Loss development Factor | G8: Expected Loss(Chain Ladder Method) | H8: Loss Reserves(Chain Ladder Method) | I8: Earned Premiums | J8: Expected Loss Ratio
C9: 2016 | D9: ='loss development'!L9 -> 2761135 | E9: 9 | F9: 1 | G9: =PRODUCT(D9,F9) -> 2761135 | H9: =G9-D9 -> 0 | I9: 4436680 | J9: =(G9/I9)*100 -> 62.234261
C10: 2017 | D10: ='loss development'!K10 -> 3153791 | E10: 8 | F10: ='year to ultimate LDF'!F17 -> 1.0168975 | G10: =PRODUCT(D10,F10) -> 3207082.2 | H10: =G10-D10 -> 53291.178 | I10: 4622303 | J10: =(G10/I10)*100 -> 69.382777
C11: 2018 | D11: ='loss development'!J11 -> 3195426 | E11: 7 | F11: ='year to ultimate LDF'!F16 -> 1.0458747 | G11: =PRODUCT(D11,F11) -> 3342015.3 | H11: =G11-D11 -> 146589.29 | I11: 4399180 | J11: =(G11/I11)*100 -> 75.969051
C12: 2019 | D12: ='loss development'!I12 -> 2881238 | E12: 6 | F12: ='year to ultimate LDF'!F15 -> 1.0794481 | G12: =PRODUCT(D12,F12) -> 3110146.9 | H12: =G12-D12 -> 228908.94 | I12: 3658064 | J12: =(G12/I12)*100 -> 85.021665
C13: 2020 | D13: ='loss development'!H13 -> 2555281 | E13: 5 | F13: ='year to ultimate LDF'!F14 -> 1.1340713 | G13: =PRODUCT(D13,F13) -> 2897870.8 | H13: =G13-D13 -> 342589.82 | I13: 4205829 | J13: =(G13/I13)*100 -> 68.901299
C14: 2021 | D14: ='loss development'!G14 -> 2780307 | E14: 4 | F14: ='year to ultimate LDF'!F13 -> 1.2038017 | G14: =PRODUCT(D14,F14) -> 3346938.3 | H14: =G14-D14 -> 566631.29 | I14: 4742233 | J14: =(G14/I14)*100 -> 70.577264
C15: 2022 | D15: ='loss development'!F15 -> 3028044 | E15: 3 | F15: ='year to ultimate LDF'!F12 -> 1.3125161 | G15: =PRODUCT(D15,F15) -> 3974356.4 | H15: =G15-D15 -> 946312.38 | I15: 5469876 | J15: =(G15/I15)*100 -> 72.658985
C16: 2023 | D16: ='loss development'!E16 -> 2690711 | E16: 2 | F16: ='year to ultimate LDF'!F11 -> 1.479144 | G16: =PRODUCT(D16,F16) -> 3979949.1 | H16: =G16-D16 -> 1289238.1 | I16: 5568740 | J16: =(G16/I16)*100 -> 71.469473
C17: 2024 | D17: ='loss development'!D17 -> 2216863 | E17: 1 | F17: ='year to ultimate LDF'!F10 -> 1.7457283 | G17: =PRODUCT(D17,F17) -> 3870040.5 | H17: =G17-D17 -> 1653177.5 | I17: 5685275 | J17: =(G17/I17)*100 -> 68.071299
C18: 2025 | D18: ='loss development'!C18 -> 1045692 | E18: 0 | F18: ='year to ultimate LDF'!F9 -> 2.9335031 | G18: =PRODUCT(D18,F18) -> 3067540.7 | H18: =G18-D18 -> 2021848.7 | I18: 5947513 | J18: =(G18/I18)*100 -> 51.576864
F19: Total | G19: =SUM(G9:G18) -> 33557075 | H19: =SUM(H9:H18) -> 7248587.3 | I19: =SUM(I9:I18) -> 48735693 | J19: =(G19/I19)*100 -> 68.855234
C28: Accident Year | D28: Cumulative paid loss to date | E28: Age at latest evaluation | F28: Ultimate Loss development Factor | G28: Expected Loss(Chain Ladder Method) | H28: Loss Reserves(Chain Ladder Method) | I28: Earned Premiums | J28: Expected Loss Ratio
C29: 2016 | D29: ='loss development'!L29 -> 1540 | E29: 9 | F29: 1 | G29: =PRODUCT(D29,F29) -> 1540 | H29: =G29-D29 -> 0 | I29: 2294 | J29: =(G29/I29)*100 -> 67.131648
C30: 2017 | D30: ='loss development'!K30 -> 1210 | E30: 8 | F30: ='year to ultimate LDF'!F37 -> 1 | G30: =PRODUCT(D30,F30) -> 1210 | H30: =G30-D30 -> 0 | I30: 2313 | J30: =(G30/I30)*100 -> 52.313013
C31: 2018 | D31: ='loss development'!J31 -> 1527 | E31: 7 | F31: ='year to ultimate LDF'!F36 -> 1.0003638 | G31: =PRODUCT(D31,F31) -> 1527.5555 | H31: =G31-D31 -> 0.55547472 | I31: 2178 | J31: =(G31/I31)*100 -> 70.135697
C32: 2019 | D32: ='loss development'!I32 -> 6196 | E32: 6 | F32: ='year to ultimate LDF'!F35 -> 1.0010661 | G32: =PRODUCT(D32,F32) -> 6202.6056 | H32: =G32-D32 -> 6.6055983 | I32: 9273 | J32: =(G32/I32)*100 -> 66.888877
C33: 2020 | D33: ='loss development'!H33 -> 16666 | E33: 5 | F33: ='year to ultimate LDF'!F34 -> 1.0035585 | G33: =PRODUCT(D33,F33) -> 16725.305 | H33: =G33-D33 -> 59.305414 | I33: 29472 | J33: =(G33/I33)*100 -> 56.749815
C34: 2021 | D34: ='loss development'!G34 -> 45701 | E34: 4 | F34: ='year to ultimate LDF'!F33 -> 1.0114308 | G34: =PRODUCT(D34,F34) -> 46223.4 | H34: =G34-D34 -> 522.4004 | I34: 52476 | J34: =(G34/I34)*100 -> 88.08484
C35: 2022 | D35: ='loss development'!F35 -> 38726 | E35: 3 | F35: ='year to ultimate LDF'!F32 -> 1.020696 | G35: =PRODUCT(D35,F35) -> 39527.471 | H35: =G35-D35 -> 801.47149 | I35: 62905 | J35: =(G35/I35)*100 -> 62.836772
C36: 2023 | D36: ='loss development'!E36 -> 37785 | E36: 2 | F36: ='year to ultimate LDF'!F31 -> 1.033878 | G36: =PRODUCT(D36,F36) -> 39065.079 | H36: =G36-D36 -> 1280.0794 | I36: 65844 | J36: =(G36/I36)*100 -> 59.329748
C37: 2024 | D37: ='loss development'!D37 -> 23980 | E37: 1 | F37: ='year to ultimate LDF'!F30 -> 1.0927673 | G37: =PRODUCT(D37,F37) -> 26204.56 | H37: =G37-D37 -> 2224.5602 | I37: 66948 | J37: =(G37/I37)*100 -> 39.141662
C38: 2025 | D38: ='loss development'!C38 -> 24301 | E38: 0 | F38: ='year to ultimate LDF'!F29 -> 1.7991902 | G38: =PRODUCT(D38,F38) -> 43722.12 | H38: =G38-D38 -> 19421.12 | I38: 62106 | J38: =(G38/I38)*100 -> 70.399189
F39: Total | G39: =SUM(G29:G38) -> 221948.1 | H39: =SUM(H29:H38) -> 24316.098 | I39: =SUM(I29:I38) -> 355809 | J39: =(G39/I39)*100 -> 62.378438
C46: Accident Year | D46: Cumulative paid loss to date | E46: Age at latest evaluation | F46: Ultimate Loss development Factor | G46: Expected Loss(Chain Ladder Method) | H46: Loss Reserves(Chain Ladder Method) | I46: Earned Premiums | J46: Expected Loss Ratio
C47: 2016
C48: 2017
C49: 2018
C50: 2019 | E50: Insufficient Info
C51: 2020
C52: 2021
C53: 2022
C54: 2023
C55: 2024
C56: 2025
C64: Accident Year | D64: Cumulative paid loss to date | E64: Age at latest evaluation | F64: Ultimate Loss development Factor | G64: Expected Loss(Chain Ladder Method) | H64: Loss Reserves(Chain Ladder Method) | I64: Earned Premiums | J64: Expected Loss Ratio
C65: 2016 | D65: ='loss development'!L65 -> 303406 | E65: 9 | F65: 1 | G65: =PRODUCT(D65,F65) -> 303406 | H65: =G65-D65 -> 0 | I65: 377433 | J65: =(G65/I65)*100 -> 80.386718
C66: 2017 | D66: ='loss development'!K66 -> 288681 | E66: 8 | F66: ='year to ultimate LDF'!F73 -> 1.0199515 | G66: =PRODUCT(D66,F66) -> 294440.63 | H66: =G66-D66 -> 5759.6261 | I66: 351006 | J66: =(G66/I66)*100 -> 83.884784
C67: 2018 | D67: ='loss development'!J67 -> 282087 | E67: 7 | F67: ='year to ultimate LDF'!F72 -> 1.031825 | G67: =PRODUCT(D67,F67) -> 291064.42 | H67: =G67-D67 -> 8977.418 | I67: 331597 | J67: =(G67/I67)*100 -> 87.776553
C68: 2019 | D68: ='loss development'!I68 -> 266627 | E68: 6 | F68: ='year to ultimate LDF'!F71 -> 1.0558969 | G68: =PRODUCT(D68,F68) -> 281530.63 | H68: =G68-D68 -> 14903.628 | I68: 318366 | J68: =(G68/I68)*100 -> 88.429866
...

Sheet rate adequacy verdict
B8: Accident Year | C8: Earned Premiums | D8: Indicative Loss Ratio(Percentage) | E8: Target Loss Ratio%(Average ) | F8: Difference(Points) | G8: Rate Adequacy Verdict
B9: 2016 | C9: 4436680 | D9: ='loss reserve and loss ratio'!J9 -> 62.234261 | E9: 68.855234 | F9: =D9-E9 -> -6.6209729 | G9: Overcharged
B10: 2017 | C10: 4622303 | D10: ='loss reserve and loss ratio'!J10 -> 69.382777 | E10: 68.855234 | F10: =D10-E10 -> 0.52754325 | G10: Roughly Adequate
B11: 2018 | C11: 4399180 | D11: ='loss reserve and loss ratio'!J11 -> 75.969051 | E11: 68.855234 | F11: =D11-E11 -> 7.1138171 | G11: Undercharged
B12: 2019 | C12: 3658064 | D12: ='loss reserve and loss ratio'!J12 -> 85.021665 | E12: 68.855234 | F12: =D12-E12 -> 16.166432 | G12: Undercharged
B13: 2020 | C13: 4205829 | D13: ='loss reserve and loss ratio'!J13 -> 68.901299 | E13: 68.855234 | F13: =D13-E13 -> 0.046065558 | G13: Roughly Adequate
B14: 2021 | C14: 4742233 | D14: ='loss reserve and loss ratio'!J14 -> 70.577264 | E14: 68.855234 | F14: =D14-E14 -> 1.7220301 | G14: Roughly Adequate
B15: 2022 | C15: 5469876 | D15: ='loss reserve and loss ratio'!J15 -> 72.658985 | E15: 68.855234 | F15: =D15-E15 -> 3.8037513 | G15: Roughly Adequate
B16: 2023 | C16: 5568740 | D16: ='loss reserve and loss ratio'!J16 -> 71.469473 | E16: 68.855234 | F16: =D16-E16 -> 2.6142393 | G16: Roughly Adequate
B17: 2024 | C17: 5685275 | D17: ='loss reserve and loss ratio'!J17 -> 68.071299 | E17: 68.855234 | F17: =D17-E17 -> -0.78393471 | G17: Roughly Adequate
B18: 2025 | C18: 5947513 | D18: ='loss reserve and loss ratio'!J18 -> 51.576864 | E18: 68.855234 | F18: =D18-E18 -> -17.278369 | G18: Overcharged
B28: Accident Year | C28: Earned Premiums | D28: Indicative Loss Ratio(Percentage) | E28: Target Loss Ratio%(Average ) | F28: Difference(Points) | G28: Rate Adequacy Verdict
B29: 2016 | C29: 2294 | D29: ='loss reserve and loss ratio'!J29 -> 67.131648 | E29: 62.378438 | F29: =D29-E29 -> 4.7532093 | G29: Roughly Adequate
B30: 2017 | C30: 2313 | D30: ='loss reserve and loss ratio'!J30 -> 52.313013 | E30: 62.378438 | F30: =D30-E30 -> -10.065425 | G30: Overcharged
B31: 2018 | C31: 2178 | D31: ='loss reserve and loss ratio'!J31 -> 70.135697 | E31: 62.378438 | F31: =D31-E31 -> 7.7572583 | G31: Undercharged
B32: 2019 | C32: 9273 | D32: ='loss reserve and loss ratio'!J32 -> 66.888877 | E32: 62.378438 | F32: =D32-E32 -> 4.5104389 | G32: Roughly Adequate
B33: 2020 | C33: 29472 | D33: ='loss reserve and loss ratio'!J33 -> 56.749815 | E33: 62.378438 | F33: =D33-E33 -> -5.6286236 | G33: Overcharged
B34: 2021 | C34: 52476 | D34: ='loss reserve and loss ratio'!J34 -> 88.08484 | E34: 62.378438 | F34: =D34-E34 -> 25.706401 | G34: Undercharged
B35: 2022 | C35: 62905 | D35: ='loss reserve and loss ratio'!J35 -> 62.836772 | E35: 62.378438 | F35: =D35-E35 -> 0.45833367 | G35: Roughly Adequate
B36: 2023 | C36: 65844 | D36: ='loss reserve and loss ratio'!J36 -> 59.329748 | E36: 62.378438 | F36: =D36-E36 -> -3.0486903 | G36: Roughly Adequate
B37: 2024 | C37: 66948 | D37: ='loss reserve and loss ratio'!J37 -> 39.141662 | E37: 62.378438 | F37: =D37-E37 -> -23.236776 | G37: Overcharged
B38: 2025 | C38: 62106 | D38: ='loss reserve and loss ratio'!J38 -> 70.399189 | E38: 62.378438 | F38: =D38-E38 -> 8.0207501 | G38: Undercharged
B46: Accident Year | C46: Earned Premiums | D46: Indicative Loss Ratio(Percentage) | E46: Target Loss Ratio%(Average ) | F46: Difference(Points) | G46: Rate Adequacy Verdict
B47: 2016
B48: 2017
B49: 2018
B50: 2019 | D50: Insufficient Info
B51: 2020
B52: 2021
B53: 2022
B54: 2023
B55: 2024
B56: 2025
B64: Accident Year | C64: Earned Premiums | D64: Indicative Loss Ratio(Percentage) | E64: Target Loss Ratio%(Average ) | F64: Difference(Points) | G64: Rate Adequacy Verdict
B65: 2016 | C65: 377433 | D65: ='loss reserve and loss ratio'!J65 -> 80.386718 | E65: 85.935343 | F65: =D65-E65 -> -5.5486253 | G65: Overcharged
B66: 2017 | C66: 351006 | D66: ='loss reserve and loss ratio'!J66 -> 83.884784 | E66: 85.935343 | F66: =D66-E66 -> -2.0505586 | G66: Roughly Adequate
B67: 2018 | C67: 331597 | D67: ='loss reserve and loss ratio'!J67 -> 87.776553 | E67: 85.935343 | F67: =D67-E67 -> 1.8412105 | G67: Roughly Adequate
B68: 2019 | C68: 318366 | D68: ='loss reserve and loss ratio'!J68 -> 88.429866 | E68: 85.935343 | F68: =D68-E68 -> 2.4945232 | G68: Roughly Adequate
B69: 2020 | C69: 347014 | D69: ='loss reserve and loss ratio'!J69 -> 74.74662 | E69: 85.935343 | F69: =D69-E69 -> -11.188723 | G69: Overcharged
B70: 2021 | C70: 377415 | D70: ='loss reserve and loss ratio'!J70 -> 90.556423 | E70: 85.935343 | F70: =D70-E70 -> 4.6210803 | G70: Roughly Adequate
...
